Workbook

Sheet Summary
A1: LogiPlan AI｜2026 物流财务演示数据
A2: 虚构求职作品集数据｜Budget 2026 V1｜Actual 截至 2026-08｜Forecast 2026-08 V1｜报告币种 CNY
A4: 年度 Budget 物流总成本 | F4: Latest Outlook 物流总成本 | K4: 全年不利差异 | P4: Cost Saving 9—12 月节省
A5: =SUMIF(Monthly_Summary!$A$5:$A$52,"BUDGET",Monthly_Summary!$I$5:$I$52) -> 16197762 | F5: =SUMIF(Monthly_Summary!$A$5:$A$52,"LATEST_OUTLOOK",Monthly_Summary!$I$5:$I$52) -> 18327463 | K5: =F5-A5 -> 2129701 | P5: =SUMIF(Monthly_Summary!$A$5:$A$52,"FORECAST",Monthly_Summary!$I$5:$I$52)-SUMIF(Monthly_Summary!$A$5:$A$52,"SCENARIO_COST_SAVING",Monthly_Summary!$I$5:$I$52) -> 168354.42
A9: 核心结论：2026 年 8 月英国为最大单月不利异常。促销拉动订单量，同时德国仓至英国的空运和 Carrier C 份额上升；五因素中结构影响最大、量影响其次。Cost Saving 仅在现有线路内调整，准时率约下降 0.19 个百分点并触发软提示，承运能力仍未验证。
A30: 月份 | B30: Budget | C30: Latest Outlook | E30: 因素 | F30: 8 月英国差异 | H30: 月份 | I30: Forecast | J30: Cost Saving | K30: 差异
A31: 1月 | B31: =Monthly_Summary!I5 -> 1194245 | C31: =Monthly_Summary!I41 -> 1193234.5 | E31: 量 | F31: =SUMIFS(Attribution!$G$5:$G$804,Attribution!$A$5:$A$804,"ACTUAL_VS_BUDGET",Attribution!$B$5:$B$804,DATE(2026,8,1),Attribution!$C$5:$C$804,"CHAIN",Attribution!$D$5:$D$804,"VOLUME",Attribution!$E$5:$E$804,"GB") -> 85239.184 | H31: 9月 | I31: =Monthly_Summary!I25 -> 1555201 | J31: =Monthly_Summary!I37 -> 1555201 | K31: =J31-I31 -> 0
A32: 2月 | B32: =Monthly_Summary!I6 -> 1174271.9 | C32: =Monthly_Summary!I42 -> 1187198.7 | E32: 结构 | F32: =SUMIFS(Attribution!$G$5:$G$804,Attribution!$A$5:$A$804,"ACTUAL_VS_BUDGET",Attribution!$B$5:$B$804,DATE(2026,8,1),Attribution!$C$5:$C$804,"CHAIN",Attribution!$D$5:$D$804,"MIX",Attribution!$E$5:$E$804,"GB") -> 324207.82 | H32: 10月 | I32: =Monthly_Summary!I26 -> 1665561.4 | J32: =Monthly_Summary!I38 -> 1631664.1 | K32: =J32-I32 -> -33897.34
A33: 3月 | B33: =Monthly_Summary!I7 -> 1244597 | C33: =Monthly_Summary!I43 -> 1276222.9 | E33: 效率 | F33: =SUMIFS(Attribution!$G$5:$G$804,Attribution!$A$5:$A$804,"ACTUAL_VS_BUDGET",Attribution!$B$5:$B$804,DATE(2026,8,1),Attribution!$C$5:$C$804,"CHAIN",Attribution!$D$5:$D$804,"EFFICIENCY",Attribution!$E$5:$E$804,"GB") -> 64558.279 | H33: 11月 | I33: =Monthly_Summary!I27 -> 1932682.4 | J33: =Monthly_Summary!I39 -> 1861844.7 | K33: =J33-I33 -> -70837.716
A34: 4月 | B34: =Monthly_Summary!I8 -> 1264916.9 | C34: =Monthly_Summary!I44 -> 1301423.8 | E34: 价 | F34: =SUMIFS(Attribution!$G$5:$G$804,Attribution!$A$5:$A$804,"ACTUAL_VS_BUDGET",Attribution!$B$5:$B$804,DATE(2026,8,1),Attribution!$C$5:$C$804,"CHAIN",Attribution!$D$5:$D$804,"PRICE",Attribution!$E$5:$E$804,"GB") -> 79960.157 | H34: 12月 | I34: =Monthly_Summary!I28 -> 2106647.8 | J34: =Monthly_Summary!I40 -> 2043028.5 | K34: =J34-I34 -> -63619.369
A35: 5月 | B35: =Monthly_Summary!I9 -> 1290786.6 | C35: =Monthly_Summary!I45 -> 1350799.6 | E35: 汇率 | F35: =SUMIFS(Attribution!$G$5:$G$804,Attribution!$A$5:$A$804,"ACTUAL_VS_BUDGET",Attribution!$B$5:$B$804,DATE(2026,8,1),Attribution!$C$5:$C$804,"CHAIN",Attribution!$D$5:$D$804,"FX",Attribution!$E$5:$E$804,"GB") -> 20508.78
A36: 6月 | B36: =Monthly_Summary!I10 -> 1311279.9 | C36: =Monthly_Summary!I46 -> 1388064.7
A37: 7月 | B37: =Monthly_Summary!I11 -> 1337669.9 | C37: =Monthly_Summary!I47 -> 1453534.1
A38: 8月 | B38: =Monthly_Summary!I12 -> 1296336.4 | C38: =Monthly_Summary!I48 -> 1916892
A39: 9月 | B39: =Monthly_Summary!I13 -> 1302117.7 | C39: =Monthly_Summary!I49 -> 1555201
A40: 10月 | B40: =Monthly_Summary!I14 -> 1402987.8 | C40: =Monthly_Summary!I50 -> 1665561.4
A41: 11月 | B41: =Monthly_Summary!I15 -> 1597075.6 | C41: =Monthly_Summary!I51 -> 1932682.4
A42: 12月 | B42: =Monthly_Summary!I16 -> 1781477.3 | C42: =Monthly_Summary!I52 -> 2106647.8

Sheet Assumptions
A1: 模型假设与版本边界
A2: 蓝色为冻结规则；黄色为本次虚构数据的演示参数。任何新业务定义应先进入 decisions.md。
A4: 类别 | B4: 项目 | C4: 取值 | D4: 说明
A5: 冻结规则 | B5: 事实粒度 | C5: month x destination_country x fulfillment_center x carrier x transport_mode | D5: 月 × 目的国 × 发货仓 × 承运商 × 运输方式
A6: 冻结规则 | B6: 报告币种 | C6: CNY | D6: 保留原币、币种和汇率字段
A7: 冻结规则 | B7: 最新结账月 | C7: 2026-08 | D7: 1—8 月 Actual；9—12 月 Forecast
A8: 冻结规则 | B8: 归因顺序 | C8: VOLUME → MIX → EFFICIENCY → PRICE → FX | D8: Shapley 32 个组合仅作后台参考
A9: 冻结规则 | B9: 变动成本范围 | C9: 6 类 | D9: 基础运费、燃油附加费、一线作业弹性人工、包装、退货物流、异常配送
A10: 冻结规则 | B10: 固定成本范围 | C10: 4 类 | D10: 仓租、一线作业基础人工、仓库管理人工、系统费用单独展示
A11: 冻结规则 | B11: 人工成本口径 | C11: D-092 | D11: 计件、加班和临时用工为变动成本；一线底薪及管理人工为固定成本
A12: 冻结规则 | B12: 订单—仓库关系 | C12: 单订单单发货仓 | D12: 仓内允许拆包并分配不同线路
A13: 冻结规则 | B13: 情景服务约束 | C13: 软提示 | D13: 允许用户保留极端情景；不作为硬阻断
A14: 冻结规则 | B14: 承运能力 | C14: MVP 未验证 | D14: 数学计算暂按无限容量，不代表供应商确认
A15: 演示参数 | B15: Growth Case | C15: 英国 9—12 月 +10% | D15: 各月相对自身 Forecast 独立调整，不复利
... A19: 技术规则 | B19: 高精度权威数据 | C19: Decimal / numeric(50,24) | D19: 工作簿公式用于审阅；JSON 保留高精度计算结果

Sheet Route_Master
A1: 有效履约线路主数据
A2: 只允许白名单线路；承运能力状态为 MVP 未验证。
A4: Route ID | B4: 目的国 | C4: 发货仓 | D4: 承运商 | E4: 运输方式 | F4: 启用日期 | G4: 停用日期 | H4: 容量状态 | I4: 目的国名称 | J4: 线路说明
A5: R_DE_DE_A_ROAD | B5: DE | C5: DE_FC | D5: CARRIER_A | E5: ROAD | F5: 46023 | H5: NOT_VALIDATED_MVP | I5: 德国 | J5: DE_FC → DE｜CARRIER_A｜ROAD
A6: R_DE_DE_B_ROAD | B6: DE | C6: DE_FC | D6: CARRIER_B | E6: ROAD | F6: 46023 | H6: NOT_VALIDATED_MVP | I6: 德国 | J6: DE_FC → DE｜CARRIER_B｜ROAD
A7: R_DE_FR_B_ROAD | B7: DE | C7: FR_FC | D7: CARRIER_B | E7: ROAD | F7: 46023 | H7: NOT_VALIDATED_MVP | I7: 德国 | J7: FR_FC → DE｜CARRIER_B｜ROAD
A8: R_FR_FR_A_ROAD | B8: FR | C8: FR_FC | D8: CARRIER_A | E8: ROAD | F8: 46023 | H8: NOT_VALIDATED_MVP | I8: 法国 | J8: FR_FC → FR｜CARRIER_A｜ROAD
A9: R_FR_FR_B_ROAD | B9: FR | C9: FR_FC | D9: CARRIER_B | E9: ROAD | F9: 46023 | H9: NOT_VALIDATED_MVP | I9: 法国 | J9: FR_FC → FR｜CARRIER_B｜ROAD
A10: R_GB_DE_A_ROAD | B10: GB | C10: DE_FC | D10: CARRIER_A | E10: ROAD | F10: 46023 | H10: NOT_VALIDATED_MVP | I10: 英国 | J10: DE_FC → GB｜CARRIER_A｜ROAD
A11: R_GB_DE_B_ROAD | B11: GB | C11: DE_FC | D11: CARRIER_B | E11: ROAD | F11: 46023 | H11: NOT_VALIDATED_MVP | I11: 英国 | J11: DE_FC → GB｜CARRIER_B｜ROAD
A12: R_GB_DE_B_AIR | B12: GB | C12: DE_FC | D12: CARRIER_B | E12: AIR | F12: 46023 | H12: NOT_VALIDATED_MVP | I12: 英国 | J12: DE_FC → GB｜CARRIER_B｜AIR
A13: R_GB_DE_C_AIR | B13: GB | C13: DE_FC | D13: CARRIER_C | E13: AIR | F13: 46023 | H13: NOT_VALIDATED_MVP | I13: 英国 | J13: DE_FC → GB｜CARRIER_C｜AIR
A14: R_GB_FR_B_AIR | B14: GB | C14: FR_FC | D14: CARRIER_B | E14: AIR | F14: 46023 | H14: NOT_VALIDATED_MVP | I14: 英国 | J14: FR_FC → GB｜CARRIER_B｜AIR

Sheet Model_Calc
A1: 线路驱动与公式计算
A2: 浅黄色列为输入；浅蓝色列为公式结果。工作簿公式用于审阅，权威高精度结果保存在生成 JSON。
A4: Version | B4: Type | C4: Scenario | D4: Month | E4: Route | F4: Destination | G4: FC | H4: Carrier | I4: Mode | J4: Total Orders | K4: Destination Share | L4: Warehouse Share | M4: Route Package Share | N4: Equivalent Orders | O4: Avg Packages/Order | P4: Packages | Q4: Avg Chargeable Weight kg | R4: Chargeable Weight kg | S4: Return Rate | T4: Return Packages | U4: Events/Package | V4: Billable Events | W4: Transport Currency | X4: Base Rate/kg | Y4: Fuel Basis | Z4: Fuel Rate/Unit | AA4: EUR/CNY | AB4: GBP/CNY | AC4: Transport FX | AD4: Base Freight Original | AE4: Fuel Original | AF4: Base Freight CNY | AG4: Fuel CNY | AH4: Variable Labor Currency | AI4: Variable Labor Unit Price | AJ4: Variable Labor FX | AK4: Variable Labor Original | AL4: Variable Labor CNY | AM4: Packaging Currency | AN4: Packaging Unit Price | AO4: Packaging FX | AP4: Packaging Original | AQ4: Packaging CNY | AR4: Return Currency | AS4: Return Unit Price | AT4: Return FX | AU4: Return Original | AV4: Return CNY | AW4: Exception Currency | AX4: Exception Unit Price | AY4: Exception FX | AZ4: Exception Original | BA4: Exception CNY | BB4: Variable Cost CNY | BC4: Expected On-time Rate | BD4: Event Note | BE4: Management Action Note | BF4: Scenario Note | BG4: Capacity Assumption
A5: BUDGET_2026_V1 | B5: BUDGET | D5: 46023 | E5: R_DE_DE_A_ROAD | F5: DE | G5: DE_FC | H5: CARRIER_A | I5: ROAD | J5: 14000 | K5: 0.42 | L5: 0.97 | M5: 0.6 | N5: =J5*K5*L5*M5 -> 3422.16 | O5: 1.05 | P5: =N5*O5 -> 3593.268 | Q5: 0.78 | R5: =P5*Q5 -> 2802.749 | S5: 0.05 | T5: =N5*S5 -> 171.108 | U5: 0.016 | V5: =P5*U5 -> 57.492288 | W5: EUR | X5: 2.2 | Y5: PERCENTAGE_OF_BASE_FREIGHT | Z5: 0.095 | AA5: 7.8 | AB5: 9 | AC5: =IF(W5="EUR",AA5,IF(W5="GBP",AB5,1)) -> 7.8 | AD5: =R5*X5 -> 6166.0479 | AE5: =IF(Y5="PERCENTAGE_OF_BASE_FREIGHT",AD5*Z5,IF(Y5="PER_CHARGEABLE_KG",R5*Z5,P5*Z5)) -> 585.77455 | AF5: =AD5*AC5 -> 48095.174 | AG5: =AE5*AC5 -> 4569.0415 | AH5: EUR | AI5: 1.18 | AJ5: =IF(AH5="EUR",AA5,IF(AH5="GBP",AB5,1)) -> 7.8 | AK5: =N5*AI5 -> 4038.1488 | AL5: =AK5*AJ5 -> 31497.561 | AM5: EUR | AN5: 0.42 | AO5: =IF(AM5="EUR",AA5,IF(AM5="GBP",AB5,1)) -> 7.8 | AP5: =P5*AN5 -> 1509.1726 | AQ5: =AP5*AO5 -> 11771.546 | AR5: EUR | AS5: 3.2 | AT5: =IF(AR5="EUR",AA5,IF(AR5="GBP",AB5,1)) -> 7.8 | AU5: =T5*AS5 -> 547.5456 | AV5: =AU5*AT5 -> 4270.8557 | AW5: EUR | AX5: 2.3 | AY5: =IF(AW5="EUR",AA5,IF(AW5="GBP",AB5,1)) -> 7.8 | AZ5: =V5*AX5 -> 132.23226 | BA5: =AZ5*AY5 -> 1031.4116 | BB5: =AF5+AG5+AL5+AQ5+AV5+BA5 -> 101235.59 | BC5: 0.965 | BG5: UNVERIFIED_UNLIMITED_FOR_MVP
A6: BUDGET_2026_V1 | B6: BUDGET | D6: 46023 | E6: R_DE_DE_B_ROAD | F6: DE | G6: DE_FC | H6: CARRIER_B | I6: ROAD | J6: 14000 | K6: 0.42 | L6: 0.97 | M6: 0.4 | N6: =J6*K6*L6*M6 -> 2281.44 | O6: 1.05 | P6: =N6*O6 -> 2395.512 | Q6: 0.8 | R6: =P6*Q6 -> 1916.4096 | S6: 0.05 | T6: =N6*S6 -> 114.072 | U6: 0.013 | V6: =P6*U6 -> 31.141656 | W6: EUR | X6: 2.75 | Y6: PER_CHARGEABLE_KG | Z6: 0.21 | AA6: 7.8 | AB6: 9 | AC6: =IF(W6="EUR",AA6,IF(W6="GBP",AB6,1)) -> 7.8 | AD6: =R6*X6 -> 5270.1264 | AE6: =IF(Y6="PERCENTAGE_OF_BASE_FREIGHT",AD6*Z6,IF(Y6="PER_CHARGEABLE_KG",R6*Z6,P6*Z6)) -> 402.44602 | AF6: =AD6*AC6 -> 41106.986 | AG6: =AE6*AC6 -> 3139.0789 | AH6: EUR | AI6: 1.18 | AJ6: =IF(AH6="EUR",AA6,IF(AH6="GBP",AB6,1)) -> 7.8 | AK6: =N6*AI6 -> 2692.0992 | AL6: =AK6*AJ6 -> 20998.374 | AM6: EUR | AN6: 0.42 | AO6: =IF(AM6="EUR",AA6,IF(AM6="GBP",AB6,1)) -> 7.8 | AP6: =P6*AN6 -> 1006.115 | AQ6: =AP6*AO6 -> 7847.6973 | AR6: EUR | AS6: 3.2 | AT6: =IF(AR6="EUR",AA6,IF(AR6="GBP",AB6,1)) -> 7.8 | AU6: =T6*AS6 -> 365.0304 | AV6: =AU6*AT6 -> 2847.2371 | AW6: EUR | AX6: 2.3 | AY6: =IF(AW6="EUR",AA6,IF(AW6="GBP",AB6,1)) -> 7.8 | AZ6: =V6*AX6 -> 71.625809 | BA6: =AZ6*AY6 -> 558.68131 | BB6: =AF6+AG6+AL6+AQ6+AV6+BA6 -> 76498.054 | BC6: 0.976 | BG6: UNVERIFIED_UNLIMITED_FOR_MVP
A7: BUDGET_2026_V1 | B7: BUDGET | D7: 46023 | E7: R_DE_FR_B_ROAD | F7: DE | G7: FR_FC | H7: CARRIER_B | I7: ROAD | J7: 14000 | K7: 0.42 | L7: 0.03 | M7: 1 | N7: =J7*K7*L7*M7 -> 176.4 | O7: 1.08 | P7: =N7*O7 -> 190.512 | Q7: 0.86 | R7: =P7*Q7 -> 163.84032 | S7: 0.05 | T7: =N7*S7 -> 8.82 | U7: 0.014 | V7: =P7*U7 -> 2.667168 | W7: EUR | X7: 3.3 | Y7: PER_CHARGEABLE_KG | Z7: 0.24 | AA7: 7.8 | AB7: 9 | AC7: =IF(W7="EUR",AA7,IF(W7="GBP",AB7,1)) -> 7.8 | AD7: =R7*X7 -> 540.67306 | AE7: =IF(Y7="PERCENTAGE_OF_BASE_FREIGHT",AD7*Z7,IF(Y7="PER_CHARGEABLE_KG",R7*Z7,P7*Z7)) -> 39.321677 | AF7: =AD7*AC7 -> 4217.2498 | AG7: =AE7*AC7 -> 306.70908 | AH7: EUR | AI7: 1.05 | AJ7: =IF(AH7="EUR",AA7,IF(AH7="GBP",AB7,1)) -> 7.8 | AK7: =N7*AI7 -> 185.22 | AL7: =AK7*AJ7 -> 1444.716 | AM7: EUR | AN7: 0.38 | AO7: =IF(AM7="EUR",AA7,IF(AM7="GBP",AB7,1)) -> 7.8 | AP7: =P7*AN7 -> 72.39456 | AQ7: =AP7*AO7 -> 564.67757 | AR7: EUR | AS7: 3.8 | AT7: =IF(AR7="EUR",AA7,IF(AR7="GBP",AB7,1)) -> 7.8 | AU7: =T7*AS7 -> 33.516 | AV7: =AU7*AT7 -> 261.4248 | AW7: EUR | AX7: 2.3 | AY7: =IF(AW7="EUR",AA7,IF(AW7="GBP",AB7,1)) -> 7.8 | AZ7: =V7*AX7 -> 6.1344864 | BA7: =AZ7*AY7 -> 47.848994 | BB7: =AF7+AG7+AL7+AQ7+AV7+BA7 -> 6842.6263 | BC7: 0.968 | BG7: UNVERIFIED_UNLIMITED_FOR_MVP
A8: BUDGET_2026_V1 | B8: BUDGET | D8: 46023 | E8: R_FR_FR_A_ROAD | F8: FR | G8: FR_FC | H8: CARRIER_A | I8: ROAD | J8: 14000 | K8: 0.32 | L8: 1 | M8: 0.35 | N8: =J8*K8*L8*M8 -> 1568 | O8: 1.06 | P8: =N8*O8 -> 1662.08 | Q8: 0.76 | R8: =P8*Q8 -> 1263.1808 | S8: 0.06 | T8: =N8*S8 -> 94.08 | U8: 0.017 | V8: =P8*U8 -> 28.25536 | W8: EUR | X8: 2.1 | Y8: PERCENTAGE_OF_BASE_FREIGHT | Z8: 0.09 | AA8: 7.8 | AB8: 9 | AC8: =IF(W8="EUR",AA8,IF(W8="GBP",AB8,1)) -> 7.8 | AD8: =R8*X8 -> 2652.6797 | AE8: =IF(Y8="PERCENTAGE_OF_BASE_FREIGHT",AD8*Z8,IF(Y8="PER_CHARGEABLE_KG",R8*Z8,P8*Z8)) -> 238.74117 | AF8: =AD8*AC8 -> 20690.902 | AG8: =AE8*AC8 -> 1862.1811 | AH8: EUR | AI8: 1.05 | AJ8: =IF(AH8="EUR",AA8,IF(AH8="GBP",AB8,1)) -> 7.8 | AK8: =N8*AI8 -> 1646.4 | AL8: =AK8*AJ8 -> 12841.92 | AM8: EUR | AN8: 0.38 | AO8: =IF(AM8="EUR",AA8,IF(AM8="GBP",AB8,1)) -> 7.8 | AP8: =P8*AN8 -> 631.5904 | AQ8: =AP8*AO8 -> 4926.4051 | AR8: EUR | AS8: 3 | AT8: =IF(AR8="EUR",AA8,IF(AR8="GBP",AB8,1)) -> 7.8 | AU8: =T8*AS8 -> 282.24 | AV8: =AU8*AT8 -> 2201.472 | AW8: EUR | AX8: 2.3 | AY8: =IF(AW8="EUR",AA8,IF(AW8="GBP",AB8,1)) -> 7.8 | AZ8: =V8*AX8 -> 64.987328 | BA8: =AZ8*AY8 -> 506.90116 | BB8: =AF8+AG8+AL8+AQ8+AV8+BA8 -> 43029.781 | BC8: 0.961 | BG8: UNVERIFIED_UNLIMITED_FOR_MVP
A9: BUDGET_2026_V1 | B9: BUDGET | D9: 46023 | E9: R_FR_FR_B_ROAD | F9: FR | G9: FR_FC | H9: CARRIER_B | I9: ROAD | J9: 14000 | K9: 0.32 | L9: 1 | M9: 0.65 | N9: =J9*K9*L9*M9 -> 2912 | O9: 1.06 | P9: =N9*O9 -> 3086.72 | Q9: 0.79 | R9: =P9*Q9 -> 2438.5088 | S9: 0.06 | T9: =N9*S9 -> 174.72 | U9: 0.014 | V9: =P9*U9 -> 43.21408 | W9: EUR | X9: 2.6 | Y9: PER_CHARGEABLE_KG | Z9: 0.2 | AA9: 7.8 | AB9: 9 | AC9: =IF(W9="EUR",AA9,IF(W9="GBP",AB9,1)) -> 7.8 | AD9: =R9*X9 -> 6340.1229 | AE9: =IF(Y9="PERCENTAGE_OF_BASE_FREIGHT",AD9*Z9,IF(Y9="PER_CHARGEABLE_KG",R9*Z9,P9*Z9)) -> 487.70176 | AF9: =AD9*AC9 -> 49452.958 | AG9: =AE9*AC9 -> 3804.0737 | AH9: EUR | AI9: 1.05 | AJ9: =IF(AH9="EUR",AA9,IF(AH9="GBP",AB9,1)) -> 7.8 | AK9: =N9*AI9 -> 3057.6 | AL9: =AK9*AJ9 -> 23849.28 | AM9: EUR | AN9: 0.38 | AO9: =IF(AM9="EUR",AA9,IF(AM9="GBP",AB9,1)) -> 7.8 | AP9: =P9*AN9 -> 1172.9536 | AQ9: =AP9*AO9 -> 9149.0381 | AR9: EUR | AS9: 3 | AT9: =IF(AR9="EUR",AA9,IF(AR9="GBP",AB9,1)) -> 7.8 | AU9: =T9*AS9 -> 524.16 | AV9: =AU9*AT9 -> 4088.448 | AW9: EUR | AX9: 2.3 | AY9: =IF(AW9="EUR",AA9,IF(AW9="GBP",AB9,1)) -> 7.8 | AZ9: =V9*AX9 -> 99.392384 | BA9: =AZ9*AY9 -> 775.2606 | BB9: =AF9+AG9+AL9+AQ9+AV9+BA9 -> 91119.059 | BC9: 0.973 | BG9: UNVERIFIED_UNLIMITED_FOR_MVP
A10: BUDGET_2026_V1 | B10: BUDGET | D10: 46023 | E10: R_GB_DE_A_ROAD | F10: GB | G10: DE_FC | H10: CARRIER_A | I10: ROAD | J10: 14000 | K10: 0.26 | L10: 0.96 | M10: 0.65 | N10: =J10*K10*L10*M10 -> 2271.36 | O10: 1.12 | P10: =N10*O10 -> 2543.9232 | Q10: 1.02 | R10: =P10*Q10 -> 2594.8017 | S10: 0.08 | T10: =N10*S10 -> 181.7088 | U10: 0.022 | V10: =P10*U10 -> 55.96631 | W10: GBP | X10: 4 | Y10: PERCENTAGE_OF_BASE_FREIGHT | Z10: 0.1 | AA10: 7.8 | AB10: 9 | AC10: =IF(W10="EUR",AA10,IF(W10="GBP",AB10,1)) -> 9 | AD10: =R10*X10 -> 10379.207 | AE10: =IF(Y10="PERCENTAGE_OF_BASE_FREIGHT",AD10*Z10,IF(Y10="PER_CHARGEABLE_KG",R10*Z10,P10*Z10)) -> 1037.9207 | AF10: =AD10*AC10 -> 93412.86 | AG10: =AE10*AC10 -> 9341.286 | AH10: EUR | AI10: 1.18 | AJ10: =IF(AH10="EUR",AA10,IF(AH10="GBP",AB10,1)) -> 7.8 | AK10: =N10*AI10 -> 2680.2048 | AL10: =AK10*AJ10 -> 20905.597 | AM10: EUR | AN10: 0.42 | AO10: =IF(AM10="EUR",AA10,IF(AM10="GBP",AB10,1)) -> 7.8 | AP10: =P10*AN10 -> 1068.4477 | AQ10: =AP10*AO10 -> 8333.8924 | AR10: GBP | AS10: 4.8 | AT10: =IF(AR10="EUR",AA10,IF(AR10="GBP",AB10,1)) -> 9 | AU10: =T10*AS10 -> 872.20224 | AV10: =AU10*AT10 -> 7849.8202 | AW10: GBP | AX10: 2.3 | AY10: =IF(AW10="EUR",AA10,IF(AW10="GBP",AB10,1)) -> 9 | AZ10: =V10*AX10 -> 128.72251 | BA10: =AZ10*AY10 -> 1158.5026 | BB10: =AF10+AG10+AL10+AQ10+AV10+BA10 -> 141001.96 | BC10: 0.93 | BG10: UNVERIFIED_UNLIMITED_FOR_MVP
A11: BUDGET_2026_V1 | B11: BUDGET | D11: 46023 | E11: R_GB_DE_B_ROAD | F11: GB | G11: DE_FC | H11: CARRIER_B | I11: ROAD | J11: 14000 | K11: 0.26 | L11: 0.96 | M11: 0.25 | N11: =J11*K11*L11*M11 -> 873.6 | O11: 1.12 | P11: =N11*O11 -> 978.432 | Q11: 1 | R11: =P11*Q11 -> 978.432 | S11: 0.08 | T11: =N11*S11 -> 69.888 | U11: 0.017 | V11: =P11*U11 -> 16.633344 | W11: GBP | X11: 4.7 | Y11: PER_CHARGEABLE_KG | Z11: 0.33 | AA11: 7.8 | AB11: 9 | AC11: =IF(W11="EUR",AA11,IF(W11="GBP",AB11,1)) -> 9 | AD11: =R11*X11 -> 4598.6304 | AE11: =IF(Y11="PERCENTAGE_OF_BASE_FREIGHT",AD11*Z11,IF(Y11="PER_CHARGEABLE_KG",R11*Z11,P11*Z11)) -> 322.88256 | AF11: =AD11*AC11 -> 41387.674 | AG11: =AE11*AC11 -> 2905.943 | AH11: EUR | AI11: 1.18 | AJ11: =IF(AH11="EUR",AA11,IF(AH11="GBP",AB11,1)) -> 7.8 | AK11: =N11*AI11 -> 1030.848 | AL11: =AK11*AJ11 -> 8040.6144 | AM11: EUR | AN11: 0.42 | AO11: =IF(AM11="EUR",AA11,IF(AM11="GBP",AB11,1)) -> 7.8 | AP11: =P11*AN11 -> 410.94144 | AQ11: =AP11*AO11 -> 3205.3432 | AR11: GBP | AS11: 4.8 | AT11: =IF(AR11="EUR",AA11,IF(AR11="GBP",AB11,1)) -> 9 | AU11: =T11*AS11 -> 335.4624 | AV11: =AU11*AT11 -> 3019.1616 | AW11: GBP | AX11: 2.3 | AY11: =IF(AW11="EUR",AA11,IF(AW11="GBP",AB11,1)) -> 9 | AZ11: =V11*AX11 -> 38.256691 | BA11: =AZ11*AY11 -> 344.31022 | BB11: =AF11+AG11+AL11+AQ11+AV11+BA11 -> 58903.046 | BC11: 0.95 | BG11: UNVERIFIED_UNLIMITED_FOR_MVP
A12: BUDGET_2026_V1 | B12: BUDGET | D12: 46023 | E12: R_GB_DE_B_AIR | F12: GB | G12: DE_FC | H12: CARRIER_B | I12: AIR | J12: 14000 | K12: 0.26 | L12: 0.96 | M12: 0.07 | N12: =J12*K12*L12*M12 -> 244.608 | O12: 1.12 | P12: =N12*O12 -> 273.96096 | Q12: 0.94 | R12: =P12*Q12 -> 257.5233 | S12: 0.08 | T12: =N12*S12 -> 19.56864 | U12: 0.013 | V12: =P12*U12 -> 3.5614925 | W12: GBP | X12: 6.2 | Y12: PERCENTAGE_OF_BASE_FREIGHT | Z12: 0.115 | AA12: 7.8 | AB12: 9 | AC12: =IF(W12="EUR",AA12,IF(W12="GBP",AB12,1)) -> 9 | AD12: =R12*X12 -> 1596.6445 | AE12: =IF(Y12="PERCENTAGE_OF_BASE_FREIGHT",AD12*Z12,IF(Y12="PER_CHARGEABLE_KG",R12*Z12,P12*Z12)) -> 183.61411 | AF12: =AD12*AC12 -> 14369.8 | AG12: =AE12*AC12 -> 1652.527 | AH12: EUR | AI12: 1.18 | AJ12: =IF(AH12="EUR",AA12,IF(AH12="GBP",AB12,1)) -> 7.8 | AK12: =N12*AI12 -> 288.63744 | AL12: =AK12*AJ12 -> 2251.372 | AM12: EUR | AN12: 0.42 | AO12: =IF(AM12="EUR",AA12,IF(AM12="GBP",AB12,1)) -> 7.8 | AP12: =P12*AN12 -> 115.0636 | AQ12: =AP12*AO12 -> 897.4961 | AR12: GBP | AS12: 4.8 | AT12: =IF(AR12="EUR",AA12,IF(AR12="GBP",AB12,1)) -> 9 | AU12: =T12*AS12 -> 93.929472 | AV12: =AU12*AT12 -> 845.36525 | AW12: GBP | AX12: 2.8 | AY12: =IF(AW12="EUR",AA12,IF(AW12="GBP",AB12,1)) -> 9 | AZ12: =V12*AX12 -> 9.9721789 | BA12: =AZ12*AY12 -> 89.74961 | BB12: =AF12+AG12+AL12+AQ12+AV12+BA12 -> 20106.31 | BC12: 0.974 | BG12: UNVERIFIED_UNLIMITED_FOR_MVP
A13: BUDGET_2026_V1 | B13: BUDGET | D13: 46023 | E13: R_GB_DE_C_AIR | F13: GB | G13: DE_FC | H13: CARRIER_C | I13: AIR | J13: 14000 | K13: 0.26 | L13: 0.96 | M13: 0.03 | N13: =J13*K13*L13*M13 -> 104.832 | O13: 1.12 | P13: =N13*O13 -> 117.41184 | Q13: 0.92 | R13: =P13*Q13 -> 108.01889 | S13: 0.08 | T13: =N13*S13 -> 8.38656 | U13: 0.009 | V13: =P13*U13 -> 1.0567066 | W13: GBP | X13: 7.5 | Y13: PER_CHARGEABLE_KG | Z13: 0.58 | AA13: 7.8 | AB13: 9 | AC13: =IF(W13="EUR",AA13,IF(W13="GBP",AB13,1)) -> 9 | AD13: =R13*X13 -> 810.1417 | AE13: =IF(Y13="PERCENTAGE_OF_BASE_FREIGHT",AD13*Z13,IF(Y13="PER_CHARGEABLE_KG",R13*Z13,P13*Z13)) -> 62.650958 | AF13: =AD13*AC13 -> 7291.2753 | AG13: =AE13*AC13 -> 563.85862 | AH13: EUR | AI13: 1.18 | AJ13: =IF(AH13="EUR",AA13,IF(AH13="GBP",AB13,1)) -> 7.8 | AK13: =N13*AI13 -> 123.70176 | AL13: =AK13*AJ13 -> 964.87373 | AM13: EUR | AN13: 0.42 | AO13: =IF(AM13="EUR",AA13,IF(AM13="GBP",AB13,1)) -> 7.8 | AP13: =P13*AN13 -> 49.312973 | AQ13: =AP13*AO13 -> 384.64119 | AR13: GBP | AS13: 4.8 | AT13: =IF(AR13="EUR",AA13,IF(AR13="GBP",AB13,1)) -> 9 | AU13: =T13*AS13 -> 40.255488 | AV13: =AU13*AT13 -> 362.29939 | AW13: GBP | AX13: 3.6 | AY13: =IF(AW13="EUR",AA13,IF(AW13="GBP",AB13,1)) -> 9 | AZ13: =V13*AX13 -> 3.8041436 | BA13: =AZ13*AY13 -> 34.237293 | BB13: =AF13+AG13+AL13+AQ13+AV13+BA13 -> 9601.1855 | BC13: 0.988 | BG13: UNVERIFIED_UNLIMITED_FOR_MVP
A14: BUDGET_2026_V1 | B14: BUDGET | D14: 46023 | E14: R_GB_FR_B_AIR | F14: GB | G14: FR_FC | H14: CARRIER_B | I14: AIR | J14: 14000 | K14: 0.26 | L14: 0.04 | M14: 1 | N14: =J14*K14*L14*M14 -> 145.6 | O14: 1.15 | P14: =N14*O14 -> 167.44 | Q14: 0.9 | R14: =P14*Q14 -> 150.696 | S14: 0.08 | T14: =N14*S14 -> 11.648 | U14: 0.012 | V14: =P14*U14 -> 2.00928 | W14: EUR | X14: 6.7 | Y14: PERCENTAGE_OF_BASE_FREIGHT | Z14: 0.105 | AA14: 7.8 | AB14: 9 | AC14: =IF(W14="EUR",AA14,IF(W14="GBP",AB14,1)) -> 7.8 | AD14: =R14*X14 -> 1009.6632 | AE14: =IF(Y14="PERCENTAGE_OF_BASE_FREIGHT",AD14*Z14,IF(Y14="PER_CHARGEABLE_KG",R14*Z14,P14*Z14)) -> 106.01464 | AF14: =AD14*AC14 -> 7875.373 | AG14: =AE14*AC14 -> 826.91416 | AH14: EUR | AI14: 1.05 | AJ14: =IF(AH14="EUR",AA14,IF(AH14="GBP",AB14,1)) -> 7.8 | AK14: =N14*AI14 -> 152.88 | AL14: =AK14*AJ14 -> 1192.464 | AM14: EUR | AN14: 0.38 | AO14: =IF(AM14="EUR",AA14,IF(AM14="GBP",AB14,1)) -> 7.8 | AP14: =P14*AN14 -> 63.6272 | AQ14: =AP14*AO14 -> 496.29216 | AR14: EUR | AS14: 5.2 | AT14: =IF(AR14="EUR",AA14,IF(AR14="GBP",AB14,1)) -> 7.8 | AU14: =T14*AS14 -> 60.5696 | AV14: =AU14*AT14 -> 472.44288 | AW14: EUR | AX14: 2.8 | AY14: =IF(AW14="EUR",AA14,IF(AW14="GBP",AB14,1)) -> 7.8 | AZ14: =V14*AX14 -> 5.625984 | BA14: =AZ14*AY14 -> 43.882675 | BB14: =AF14+AG14+AL14+AQ14+AV14+BA14 -> 10907.369 | BC14: 0.971 | BG14: UNVERIFIED_UNLIMITED_FOR_MVP
A15: BUDGET_2026_V1 | B15: BUDGET | D15: 46054 | E15: R_DE_DE_A_ROAD | F15: DE | G15: DE_FC | H15: CARRIER_A | I15: ROAD | J15: 13500 | K15: 0.42 | L15: 0.97 | M15: 0.6 | N15: =J15*K15*L15*M15 -> 3299.94 | O15: 1.05 | P15: =N15*O15 -> 3464.937 | Q15: 0.78 | R15: =P15*Q15 -> 2702.6509 | S15: 0.05 | T15: =N15*S15 -> 164.997 | U15: 0.016 | V15: =P15*U15 -> 55.438992 | W15: EUR | X15: 2.2 | Y15: PERCENTAGE_OF_BASE_FREIGHT | Z15: 0.095 | AA15: 7.8 | AB15: 9 | AC15: =IF(W15="EUR",AA15,IF(W15="GBP",AB15,1)) -> 7.8 | AD15: =R15*X15 -> 5945.8319 | AE15: =IF(Y15="PERCENTAGE_OF_BASE_FREIGHT",AD15*Z15,IF(Y15="PER_CHARGEABLE_KG",R15*Z15,P15*Z15)) -> 564.85403 | AF15: =AD15*AC15 -> 46377.489 | AG15: =AE15*AC15 -> 4405.8614 | AH15: EUR | AI15: 1.18 | AJ15: =IF(AH15="EUR",AA15,IF(AH15="GBP",AB15,1)) -> 7.8 | AK15: =N15*AI15 -> 3893.9292 | AL15: =AK15*AJ15 -> 30372.648 | AM15: EUR | AN15: 0.42 | AO15: =IF(AM15="EUR",AA15,IF(AM15="GBP",AB15,1)) -> 7.8 | AP15: =P15*AN15 -> 1455.2735 | AQ15: =AP15*AO15 -> 11351.134 | AR15: EUR | AS15: 3.2 | AT15: =IF(AR15="EUR",AA15,IF(AR15="GBP",AB15,1)) -> 7.8 | AU15: =T15*AS15 -> 527.9904 | AV15: =AU15*AT15 -> 4118.3251 | AW15: EUR | AX15: 2.3 | AY15: =IF(AW15="EUR",AA15,IF(AW15="GBP",AB15,1)) -> 7.8 | AZ15: =V15*AX15 -> 127.50968 | BA15: =AZ15*AY15 -> 994.57552 | BB15: =AF15+AG15+AL15+AQ15+AV15+BA15 -> 97620.032 | BC15: 0.965 | BG15: UNVERIFIED_UNLIMITED_FOR_MVP
A16: BUDGET_2026_V1 | B16: BUDGET | D16: 46054 | E16: R_DE_DE_B_ROAD | F16: DE | G16: DE_FC | H16: CARRIER_B | I16: ROAD | J16: 13500 | K16: 0.42 | L16: 0.97 | M16: 0.4 | N16: =J16*K16*L16*M16 -> 2199.96 | O16: 1.05 | P16: =N16*O16 -> 2309.958 | Q16: 0.8 | R16: =P16*Q16 -> 1847.9664 | S16: 0.05 | T16: =N16*S16 -> 109.998 | U16: 0.013 | V16: =P16*U16 -> 30.029454 | W16: EUR | X16: 2.75 | Y16: PER_CHARGEABLE_KG | Z16: 0.21 | AA16: 7.8 | AB16: 9 | AC16: =IF(W16="EUR",AA16,IF(W16="GBP",AB16,1)) -> 7.8 | AD16: =R16*X16 -> 5081.9076 | AE16: =IF(Y16="PERCENTAGE_OF_BASE_FREIGHT",AD16*Z16,IF(Y16="PER_CHARGEABLE_KG",R16*Z16,P16*Z16)) -> 388.07294 | AF16: =AD16*AC16 -> 39638.879 | AG16: =AE16*AC16 -> 3026.969 | AH16: EUR | AI16: 1.18 | AJ16: =IF(AH16="EUR",AA16,IF(AH16="GBP",AB16,1)) -> 7.8 | AK16: =N16*AI16 -> 2595.9528 | AL16: =AK16*AJ16 -> 20248.432 | AM16: EUR | AN16: 0.42 | AO16: =IF(AM16="EUR",AA16,IF(AM16="GBP",AB16,1)) -> 7.8 | AP16: =P16*AN16 -> 970.18236 | AQ16: =AP16*AO16 -> 7567.4224 | AR16: EUR | AS16: 3.2 | AT16: =IF(AR16="EUR",AA16,IF(AR16="GBP",AB16,1)) -> 7.8 | AU16: =T16*AS16 -> 351.9936 | AV16: =AU16*AT16 -> 2745.5501 | AW16: EUR | AX16: 2.3 | AY16: =IF(AW16="EUR",AA16,IF(AW16="GBP",AB16,1)) -> 7.8 | AZ16: =V16*AX16 -> 69.067744 | BA16: =AZ16*AY16 -> 538.7284 | BB16: =AF16+AG16+AL16+AQ16+AV16+BA16 -> 73765.981 | BC16: 0.976 | BG16: UNVERIFIED_UNLIMITED_FOR_MVP
... A74: BUDGET_2026_V1 | B74: BUDGET | D74: 46204 | E74: R_GB_FR_B_AIR | F74: GB | G74: FR_FC | H74: CARRIER_B | I74: AIR | J74: 17000 | K74: 0.3 | L74: 0.04 | M74: 1 | N74: =J74*K74*L74*M74 -> 204 | O74: 1.15 | P74: =N74*O74 -> 234.6 | Q74: 0.9 | R74: =P74*Q74 -> 211.14 | S74: 0.08 | T74: =N74*S74 -> 16.32 | U74: 0.012 | V74: =P74*U74 -> 2.8152 | W74: EUR | X74: 6.7 | Y74: PERCENTAGE_OF_BASE_FREIGHT | Z74: 0.105 | AA74: 7.8 | AB74: 9 | AC74: =IF(W74="EUR",AA74,IF(W74="GBP",AB74,1)) -> 7.8 | AD74: =R74*X74 -> 1414.638 | AE74: =IF(Y74="PERCENTAGE_OF_BASE_FREIGHT",AD74*Z74,IF(Y74="PER_CHARGEABLE_KG",R74*Z74,P74*Z74)) -> 148.53699 | AF74: =AD74*AC74 -> 11034.176 | AG74: =AE74*AC74 -> 1158.5885 | AH74: EUR | AI74: 1.05 | AJ74: =IF(AH74="EUR",AA74,IF(AH74="GBP",AB74,1)) -> 7.8 | AK74: =N74*AI74 -> 214.2 | AL74: =AK74*AJ74 -> 1670.76 | AM74: EUR | AN74: 0.38 | AO74: =IF(AM74="EUR",AA74,IF(AM74="GBP",AB74,1)) -> 7.8 | AP74: =P74*AN74 -> 89.148 | AQ74: =AP74*AO74 -> 695.3544 | AR74: EUR | AS74: 5.2 | AT74: =IF(AR74="EUR",AA74,IF(AR74="GBP",AB74,1)) -> 7.8 | AU74: =T74*AS74 -> 84.864 | AV74: =AU74*AT74 -> 661.9392 | AW74: EUR | AX74: 2.8 | AY74: =IF(AW74="EUR",AA74,IF(AW74="GBP",AB74,1)) -> 7.8 | AZ74: =V74*AX74 -> 7.88256 | BA74: =AZ74*AY74 -> 61.483968 | BB74: =AF74+AG74+AL74+AQ74+AV74+BA74 -> 15282.302 | BC74: 0.971 | BG74: UNVERIFIED_UNLIMITED_FOR_MVP
A75: BUDGET_2026_V1 | B75: BUDGET | D75: 46235 | E75: R_DE_DE_A_ROAD | F75: DE | G75: DE_FC | H75: CARRIER_A | I75: ROAD | J75: 16000 | K75: 0.38 | L75: 0.97 | M75: 0.6 | N75: =J75*K75*L75*M75 -> 3538.56 | O75: 1.05 | P75: =N75*O75 -> 3715.488 | Q75: 0.78 | R75: =P75*Q75 -> 2898.0806 | S75: 0.05 | T75: =N75*S75 -> 176.928 | U75: 0.016 | V75: =P75*U75 -> 59.447808 | W75: EUR | X75: 2.2 | Y75: PERCENTAGE_OF_BASE_FREIGHT | Z75: 0.095 | AA75: 7.8 | AB75: 9 | AC75: =IF(W75="EUR",AA75,IF(W75="GBP",AB75,1)) -> 7.8 | AD75: =R75*X75 -> 6375.7774 | AE75: =IF(Y75="PERCENTAGE_OF_BASE_FREIGHT",AD75*Z75,IF(Y75="PER_CHARGEABLE_KG",R75*Z75,P75*Z75)) -> 605.69885 | AF75: =AD75*AC75 -> 49731.064 | AG75: =AE75*AC75 -> 4724.4511 | AH75: EUR | AI75: 1.18 | AJ75: =IF(AH75="EUR",AA75,IF(AH75="GBP",AB75,1)) -> 7.8 | AK75: =N75*AI75 -> 4175.5008 | AL75: =AK75*AJ75 -> 32568.906 | AM75: EUR | AN75: 0.42 | AO75: =IF(AM75="EUR",AA75,IF(AM75="GBP",AB75,1)) -> 7.8 | AP75: =P75*AN75 -> 1560.505 | AQ75: =AP75*AO75 -> 12171.939 | AR75: EUR | AS75: 3.2 | AT75: =IF(AR75="EUR",AA75,IF(AR75="GBP",AB75,1)) -> 7.8 | AU75: =T75*AS75 -> 566.1696 | AV75: =AU75*AT75 -> 4416.1229 | AW75: EUR | AX75: 2.3 | AY75: =IF(AW75="EUR",AA75,IF(AW75="GBP",AB75,1)) -> 7.8 | AZ75: =V75*AX75 -> 136.72996 | BA75: =AZ75*AY75 -> 1066.4937 | BB75: =AF75+AG75+AL75+AQ75+AV75+BA75 -> 104678.98 | BC75: 0.965 | BD75: UK promotion | BG75: UNVERIFIED_UNLIMITED_FOR_MVP
A76: BUDGET_2026_V1 | B76: BUDGET | D76: 46235 | E76: R_DE_DE_B_ROAD | F76: DE | G76: DE_FC | H76: CARRIER_B | I76: ROAD | J76: 16000 | K76: 0.38 | L76: 0.97 | M76: 0.4 | N76: =J76*K76*L76*M76 -> 2359.04 | O76: 1.05 | P76: =N76*O76 -> 2476.992 | Q76: 0.8 | R76: =P76*Q76 -> 1981.5936 | S76: 0.05 | T76: =N76*S76 -> 117.952 | U76: 0.013 | V76: =P76*U76 -> 32.200896 | W76: EUR | X76: 2.75 | Y76: PER_CHARGEABLE_KG | Z76: 0.21 | AA76: 7.8 | AB76: 9 | AC76: =IF(W76="EUR",AA76,IF(W76="GBP",AB76,1)) -> 7.8 | AD76: =R76*X76 -> 5449.3824 | AE76: =IF(Y76="PERCENTAGE_OF_BASE_FREIGHT",AD76*Z76,IF(Y76="PER_CHARGEABLE_KG",R76*Z76,P76*Z76)) -> 416.13466 | AF76: =AD76*AC76 -> 42505.183 | AG76: =AE76*AC76 -> 3245.8503 | AH76: EUR | AI76: 1.18 | AJ76: =IF(AH76="EUR",AA76,IF(AH76="GBP",AB76,1)) -> 7.8 | AK76: =N76*AI76 -> 2783.6672 | AL76: =AK76*AJ76 -> 21712.604 | AM76: EUR | AN76: 0.42 | AO76: =IF(AM76="EUR",AA76,IF(AM76="GBP",AB76,1)) -> 7.8 | AP76: =P76*AN76 -> 1040.3366 | AQ76: =AP76*AO76 -> 8114.6258 | AR76: EUR | AS76: 3.2 | AT76: =IF(AR76="EUR",AA76,IF(AR76="GBP",AB76,1)) -> 7.8 | AU76: =T76*AS76 -> 377.4464 | AV76: =AU76*AT76 -> 2944.0819 | AW76: EUR | AX76: 2.3 | AY76: =IF(AW76="EUR",AA76,IF(AW76="GBP",AB76,1)) -> 7.8 | AZ76: =V76*AX76 -> 74.062061 | BA76: =AZ76*AY76 -> 577.68407 | BB76: =AF76+AG76+AL76+AQ76+AV76+BA76 -> 79100.029 | BC76: 0.976 | BD76: UK promotion | BG76: UNVERIFIED_UNLIMITED_FOR_MVP
A77: BUDGET_2026_V1 | B77: BUDGET | D77: 46235 | E77: R_DE_FR_B_ROAD | F77: DE | G77: FR_FC | H77: CARRIER_B | I77: ROAD | J77: 16000 | K77: 0.38 | L77: 0.03 | M77: 1 | N77: =J77*K77*L77*M77 -> 182.4 | O77: 1.08 | P77: =N77*O77 -> 196.992 | Q77: 0.86 | R77: =P77*Q77 -> 169.41312 | S77: 0.05 | T77: =N77*S77 -> 9.12 | U77: 0.014 | V77: =P77*U77 -> 2.757888 | W77: EUR | X77: 3.3 | Y77: PER_CHARGEABLE_KG | Z77: 0.24 | AA77: 7.8 | AB77: 9 | AC77: =IF(W77="EUR",AA77,IF(W77="GBP",AB77,1)) -> 7.8 | AD77: =R77*X77 -> 559.0633 | AE77: =IF(Y77="PERCENTAGE_OF_BASE_FREIGHT",AD77*Z77,IF(Y77="PER_CHARGEABLE_KG",R77*Z77,P77*Z77)) -> 40.659149 | AF77: =AD77*AC77 -> 4360.6937 | AG77: =AE77*AC77 -> 317.14136 | AH77: EUR | AI77: 1.05 | AJ77: =IF(AH77="EUR",AA77,IF(AH77="GBP",AB77,1)) -> 7.8 | AK77: =N77*AI77 -> 191.52 | AL77: =AK77*AJ77 -> 1493.856 | AM77: EUR | AN77: 0.38 | AO77: =IF(AM77="EUR",AA77,IF(AM77="GBP",AB77,1)) -> 7.8 | AP77: =P77*AN77 -> 74.85696 | AQ77: =AP77*AO77 -> 583.88429 | AR77: EUR | AS77: 3.8 | AT77: =IF(AR77="EUR",AA77,IF(AR77="GBP",AB77,1)) -> 7.8 | AU77: =T77*AS77 -> 34.656 | AV77: =AU77*AT77 -> 270.3168 | AW77: EUR | AX77: 2.3 | AY77: =IF(AW77="EUR",AA77,IF(AW77="GBP",AB77,1)) -> 7.8 | AZ77: =V77*AX77 -> 6.3431424 | BA77: =AZ77*AY77 -> 49.476511 | BB77: =AF77+AG77+AL77+AQ77+AV77+BA77 -> 7075.3687 | BC77: 0.968 | BD77: UK promotion | BG77: UNVERIFIED_UNLIMITED_FOR_MVP
A78: BUDGET_2026_V1 | B78: BUDGET | D78: 46235 | E78: R_FR_FR_A_ROAD | F78: FR | G78: FR_FC | H78: CARRIER_A | I78: ROAD | J78: 16000 | K78: 0.32 | L78: 1 | M78: 0.35 | N78: =J78*K78*L78*M78 -> 1792 | O78: 1.06 | P78: =N78*O78 -> 1899.52 | Q78: 0.76 | R78: =P78*Q78 -> 1443.6352 | S78: 0.06 | T78: =N78*S78 -> 107.52 | U78: 0.017 | V78: =P78*U78 -> 32.29184 | W78: EUR | X78: 2.1 | Y78: PERCENTAGE_OF_BASE_FREIGHT | Z78: 0.09 | AA78: 7.8 | AB78: 9 | AC78: =IF(W78="EUR",AA78,IF(W78="GBP",AB78,1)) -> 7.8 | AD78: =R78*X78 -> 3031.6339 | AE78: =IF(Y78="PERCENTAGE_OF_BASE_FREIGHT",AD78*Z78,IF(Y78="PER_CHARGEABLE_KG",R78*Z78,P78*Z78)) -> 272.84705 | AF78: =AD78*AC78 -> 23646.745 | AG78: =AE78*AC78 -> 2128.207 | AH78: EUR | AI78: 1.05 | AJ78: =IF(AH78="EUR",AA78,IF(AH78="GBP",AB78,1)) -> 7.8 | AK78: =N78*AI78 -> 1881.6 | AL78: =AK78*AJ78 -> 14676.48 | AM78: EUR | AN78: 0.38 | AO78: =IF(AM78="EUR",AA78,IF(AM78="GBP",AB78,1)) -> 7.8 | AP78: =P78*AN78 -> 721.8176 | AQ78: =AP78*AO78 -> 5630.1773 | AR78: EUR | AS78: 3 | AT78: =IF(AR78="EUR",AA78,IF(AR78="GBP",AB78,1)) -> 7.8 | AU78: =T78*AS78 -> 322.56 | AV78: =AU78*AT78 -> 2515.968 | AW78: EUR | AX78: 2.3 | AY78: =IF(AW78="EUR",AA78,IF(AW78="GBP",AB78,1)) -> 7.8 | AZ78: =V78*AX78 -> 74.271232 | BA78: =AZ78*AY78 -> 579.31561 | BB78: =AF78+AG78+AL78+AQ78+AV78+BA78 -> 49176.892 | BC78: 0.961 | BD78: UK promotion | BG78: UNVERIFIED_UNLIMITED_FOR_MVP
A79: BUDGET_2026_V1 | B79: BUDGET | D79: 46235 | E79: R_FR_FR_B_ROAD | F79: FR | G79: FR_FC | H79: CARRIER_B | I79: ROAD | J79: 16000 | K79: 0.32 | L79: 1 | M79: 0.65 | N79: =J79*K79*L79*M79 -> 3328 | O79: 1.06 | P79: =N79*O79 -> 3527.68 | Q79: 0.79 | R79: =P79*Q79 -> 2786.8672 | S79: 0.06 | T79: =N79*S79 -> 199.68 | U79: 0.014 | V79: =P79*U79 -> 49.38752 | W79: EUR | X79: 2.6 | Y79: PER_CHARGEABLE_KG | Z79: 0.2 | AA79: 7.8 | AB79: 9 | AC79: =IF(W79="EUR",AA79,IF(W79="GBP",AB79,1)) -> 7.8 | AD79: =R79*X79 -> 7245.8547 | AE79: =IF(Y79="PERCENTAGE_OF_BASE_FREIGHT",AD79*Z79,IF(Y79="PER_CHARGEABLE_KG",R79*Z79,P79*Z79)) -> 557.37344 | AF79: =AD79*AC79 -> 56517.667 | AG79: =AE79*AC79 -> 4347.5128 | AH79: EUR | AI79: 1.05 | AJ79: =IF(AH79="EUR",AA79,IF(AH79="GBP",AB79,1)) -> 7.8 | AK79: =N79*AI79 -> 3494.4 | AL79: =AK79*AJ79 -> 27256.32 | AM79: EUR | AN79: 0.38 | AO79: =IF(AM79="EUR",AA79,IF(AM79="GBP",AB79,1)) -> 7.8 | AP79: =P79*AN79 -> 1340.5184 | AQ79: =AP79*AO79 -> 10456.044 | AR79: EUR | AS79: 3 | AT79: =IF(AR79="EUR",AA79,IF(AR79="GBP",AB79,1)) -> 7.8 | AU79: =T79*AS79 -> 599.04 | AV79: =AU79*AT79 -> 4672.512 | AW79: EUR | AX79: 2.3 | AY79: =IF(AW79="EUR",AA79,IF(AW79="GBP",AB79,1)) -> 7.8 | AZ79: =V79*AX79 -> 113.5913 | BA79: =AZ79*AY79 -> 886.01211 | BB79: =AF79+AG79+AL79+AQ79+AV79+BA79 -> 104136.07 | BC79: 0.973 | BD79: UK promotion | BG79: UNVERIFIED_UNLIMITED_FOR_MVP
A80: BUDGET_2026_V1 | B80: BUDGET | D80: 46235 | E80: R_GB_DE_A_ROAD | F80: GB | G80: DE_FC | H80: CARRIER_A | I80: ROAD | J80: 16000 | K80: 0.3 | L80: 0.96 | M80: 0.65 | N80: =J80*K80*L80*M80 -> 2995.2 | O80: 1.12 | P80: =N80*O80 -> 3354.624 | Q80: 1.02 | R80: =P80*Q80 -> 3421.7165 | S80: 0.08 | T80: =N80*S80 -> 239.616 | U80: 0.022 | V80: =P80*U80 -> 73.801728 | W80: GBP | X80: 4 | Y80: PERCENTAGE_OF_BASE_FREIGHT | Z80: 0.1 | AA80: 7.8 | AB80: 9 | AC80: =IF(W80="EUR",AA80,IF(W80="GBP",AB80,1)) -> 9 | AD80: =R80*X80 -> 13686.866 | AE80: =IF(Y80="PERCENTAGE_OF_BASE_FREIGHT",AD80*Z80,IF(Y80="PER_CHARGEABLE_KG",R80*Z80,P80*Z80)) -> 1368.6866 | AF80: =AD80*AC80 -> 123181.79 | AG80: =AE80*AC80 -> 12318.179 | AH80: EUR | AI80: 1.18 | AJ80: =IF(AH80="EUR",AA80,IF(AH80="GBP",AB80,1)) -> 7.8 | AK80: =N80*AI80 -> 3534.336 | AL80: =AK80*AJ80 -> 27567.821 | AM80: EUR | AN80: 0.42 | AO80: =IF(AM80="EUR",AA80,IF(AM80="GBP",AB80,1)) -> 7.8 | AP80: =P80*AN80 -> 1408.9421 | AQ80: =AP80*AO80 -> 10989.748 | AR80: GBP | AS80: 4.8 | AT80: =IF(AR80="EUR",AA80,IF(AR80="GBP",AB80,1)) -> 9 | AU80: =T80*AS80 -> 1150.1568 | AV80: =AU80*AT80 -> 10351.411 | AW80: GBP | AX80: 2.3 | AY80: =IF(AW80="EUR",AA80,IF(AW80="GBP",AB80,1)) -> 9 | AZ80: =V80*AX80 -> 169.74397 | BA80: =AZ80*AY80 -> 1527.6958 | BB80: =AF80+AG80+AL80+AQ80+AV80+BA80 -> 185936.65 | BC80: 0.93 | BD80: UK promotion | BG80: UNVERIFIED_UNLIMITED_FOR_MVP
A81: BUDGET_2026_V1 | B81: BUDGET | D81: 46235 | E81: R_GB_DE_B_ROAD | F81: GB | G81: DE_FC | H81: CARRIER_B | I81: ROAD | J81: 16000 | K81: 0.3 | L81: 0.96 | M81: 0.25 | N81: =J81*K81*L81*M81 -> 1152 | O81: 1.12 | P81: =N81*O81 -> 1290.24 | Q81: 1 | R81: =P81*Q81 -> 1290.24 | S81: 0.08 | T81: =N81*S81 -> 92.16 | U81: 0.017 | V81: =P81*U81 -> 21.93408 | W81: GBP | X81: 4.7 | Y81: PER_CHARGEABLE_KG | Z81: 0.33 | AA81: 7.8 | AB81: 9 | AC81: =IF(W81="EUR",AA81,IF(W81="GBP",AB81,1)) -> 9 | AD81: =R81*X81 -> 6064.128 | AE81: =IF(Y81="PERCENTAGE_OF_BASE_FREIGHT",AD81*Z81,IF(Y81="PER_CHARGEABLE_KG",R81*Z81,P81*Z81)) -> 425.7792 | AF81: =AD81*AC81 -> 54577.152 | AG81: =AE81*AC81 -> 3832.0128 | AH81: EUR | AI81: 1.18 | AJ81: =IF(AH81="EUR",AA81,IF(AH81="GBP",AB81,1)) -> 7.8 | AK81: =N81*AI81 -> 1359.36 | AL81: =AK81*AJ81 -> 10603.008 | AM81: EUR | AN81: 0.42 | AO81: =IF(AM81="EUR",AA81,IF(AM81="GBP",AB81,1)) -> 7.8 | AP81: =P81*AN81 -> 541.9008 | AQ81: =AP81*AO81 -> 4226.8262 | AR81: GBP | AS81: 4.8 | AT81: =IF(AR81="EUR",AA81,IF(AR81="GBP",AB81,1)) -> 9 | AU81: =T81*AS81 -> 442.368 | AV81: =AU81*AT81 -> 3981.312 | AW81: GBP | AX81: 2.3 | AY81: =IF(AW81="EUR",AA81,IF(AW81="GBP",AB81,1)) -> 9 | AZ81: =V81*AX81 -> 50.448384 | BA81: =AZ81*AY81 -> 454.03546 | BB81: =AF81+AG81+AL81+AQ81+AV81+BA81 -> 77674.346 | BC81: 0.95 | BD81: UK promotion | BG81: UNVERIFIED_UNLIMITED_FOR_MVP
A82: BUDGET_2026_V1 | B82: BUDGET | D82: 46235 | E82: R_GB_DE_B_AIR | F82: GB | G82: DE_FC | H82: CARRIER_B | I82: AIR | J82: 16000 | K82: 0.3 | L82: 0.96 | M82: 0.07 | N82: =J82*K82*L82*M82 -> 322.56 | O82: 1.12 | P82: =N82*O82 -> 361.2672 | Q82: 0.94 | R82: =P82*Q82 -> 339.59117 | S82: 0.08 | T82: =N82*S82 -> 25.8048 | U82: 0.013 | V82: =P82*U82 -> 4.6964736 | W82: GBP | X82: 6.2 | Y82: PERCENTAGE_OF_BASE_FREIGHT | Z82: 0.115 | AA82: 7.8 | AB82: 9 | AC82: =IF(W82="EUR",AA82,IF(W82="GBP",AB82,1)) -> 9 | AD82: =R82*X82 -> 2105.4652 | AE82: =IF(Y82="PERCENTAGE_OF_BASE_FREIGHT",AD82*Z82,IF(Y82="PER_CHARGEABLE_KG",R82*Z82,P82*Z82)) -> 242.1285 | AF82: =AD82*AC82 -> 18949.187 | AG82: =AE82*AC82 -> 2179.1565 | AH82: EUR | AI82: 1.18 | AJ82: =IF(AH82="EUR",AA82,IF(AH82="GBP",AB82,1)) -> 7.8 | AK82: =N82*AI82 -> 380.6208 | AL82: =AK82*AJ82 -> 2968.8422 | AM82: EUR | AN82: 0.42 | AO82: =IF(AM82="EUR",AA82,IF(AM82="GBP",AB82,1)) -> 7.8 | AP82: =P82*AN82 -> 151.73222 | AQ82: =AP82*AO82 -> 1183.5113 | AR82: GBP | AS82: 4.8 | AT82: =IF(AR82="EUR",AA82,IF(AR82="GBP",AB82,1)) -> 9 | AU82: =T82*AS82 -> 123.86304 | AV82: =AU82*AT82 -> 1114.7674 | AW82: GBP | AX82: 2.8 | AY82: =IF(AW82="EUR",AA82,IF(AW82="GBP",AB82,1)) -> 9 | AZ82: =V82*AX82 -> 13.150126 | BA82: =AZ82*AY82 -> 118.35113 | BB82: =AF82+AG82+AL82+AQ82+AV82+BA82 -> 26513.816 | BC82: 0.974 | BD82: UK promotion | BG82: UNVERIFIED_UNLIMITED_FOR_MVP
A83: BUDGET_2026_V1 | B83: BUDGET | D83: 46235 | E83: R_GB_DE_C_AIR | F83: GB | G83: DE_FC | H83: CARRIER_C | I83: AIR | J83: 16000 | K83: 0.3 | L83: 0.96 | M83: 0.03 | N83: =J83*K83*L83*M83 -> 138.24 | O83: 1.12 | P83: =N83*O83 -> 154.8288 | Q83: 0.92 | R83: =P83*Q83 -> 142.4425 | S83: 0.08 | T83: =N83*S83 -> 11.0592 | U83: 0.009 | V83: =P83*U83 -> 1.3934592 | W83: GBP | X83: 7.5 | Y83: PER_CHARGEABLE_KG | Z83: 0.58 | AA83: 7.8 | AB83: 9 | AC83: =IF(W83="EUR",AA83,IF(W83="GBP",AB83,1)) -> 9 | AD83: =R83*X83 -> 1068.3187 | AE83: =IF(Y83="PERCENTAGE_OF_BASE_FREIGHT",AD83*Z83,IF(Y83="PER_CHARGEABLE_KG",R83*Z83,P83*Z83)) -> 82.616648 | AF83: =AD83*AC83 -> 9614.8685 | AG83: =AE83*AC83 -> 743.54983 | AH83: EUR | AI83: 1.18 | AJ83: =IF(AH83="EUR",AA83,IF(AH83="GBP",AB83,1)) -> 7.8 | AK83: =N83*AI83 -> 163.1232 | AL83: =AK83*AJ83 -> 1272.361 | AM83: EUR | AN83: 0.42 | AO83: =IF(AM83="EUR",AA83,IF(AM83="GBP",AB83,1)) -> 7.8 | AP83: =P83*AN83 -> 65.028096 | AQ83: =AP83*AO83 -> 507.21915 | AR83: GBP | AS83: 4.8 | AT83: =IF(AR83="EUR",AA83,IF(AR83="GBP",AB83,1)) -> 9 | AU83: =T83*AS83 -> 53.08416 | AV83: =AU83*AT83 -> 477.75744 | AW83: GBP | AX83: 3.6 | AY83: =IF(AW83="EUR",AA83,IF(AW83="GBP",AB83,1)) -> 9 | AZ83: =V83*AX83 -> 5.0164531 | BA83: =AZ83*AY83 -> 45.148078 | BB83: =AF83+AG83+AL83+AQ83+AV83+BA83 -> 12660.904 | BC83: 0.988 | BD83: UK promotion | BG83: UNVERIFIED_UNLIMITED_FOR_MVP
A84: BUDGET_2026_V1 | B84: BUDGET | D84: 46235 | E84: R_GB_FR_B_AIR | F84: GB | G84: FR_FC | H84: CARRIER_B | I84: AIR | J84: 16000 | K84: 0.3 | L84: 0.04 | M84: 1 | N84: =J84*K84*L84*M84 -> 192 | O84: 1.15 | P84: =N84*O84 -> 220.8 | Q84: 0.9 | R84: =P84*Q84 -> 198.72 | S84: 0.08 | T84: =N84*S84 -> 15.36 | U84: 0.012 | V84: =P84*U84 -> 2.6496 | W84: EUR | X84: 6.7 | Y84: PERCENTAGE_OF_BASE_FREIGHT | Z84: 0.105 | AA84: 7.8 | AB84: 9 | AC84: =IF(W84="EUR",AA84,IF(W84="GBP",AB84,1)) -> 7.8 | AD84: =R84*X84 -> 1331.424 | AE84: =IF(Y84="PERCENTAGE_OF_BASE_FREIGHT",AD84*Z84,IF(Y84="PER_CHARGEABLE_KG",R84*Z84,P84*Z84)) -> 139.79952 | AF84: =AD84*AC84 -> 10385.107 | AG84: =AE84*AC84 -> 1090.4363 | AH84: EUR | AI84: 1.05 | AJ84: =IF(AH84="EUR",AA84,IF(AH84="GBP",AB84,1)) -> 7.8 | AK84: =N84*AI84 -> 201.6 | AL84: =AK84*AJ84 -> 1572.48 | AM84: EUR | AN84: 0.38 | AO84: =IF(AM84="EUR",AA84,IF(AM84="GBP",AB84,1)) -> 7.8 | AP84: =P84*AN84 -> 83.904 | AQ84: =AP84*AO84 -> 654.4512 | AR84: EUR | AS84: 5.2 | AT84: =IF(AR84="EUR",AA84,IF(AR84="GBP",AB84,1)) -> 7.8 | AU84: =T84*AS84 -> 79.872 | AV84: =AU84*AT84 -> 623.0016 | AW84: EUR | AX84: 2.8 | AY84: =IF(AW84="EUR",AA84,IF(AW84="GBP",AB84,1)) -> 7.8 | AZ84: =V84*AX84 -> 7.41888 | BA84: =AZ84*AY84 -> 57.867264 | BB84: =AF84+AG84+AL84+AQ84+AV84+BA84 -> 14383.344 | BC84: 0.971 | BD84: UK promotion | BG84: UNVERIFIED_UNLIMITED_FOR_MVP
A85: BUDGET_2026_V1 | B85: BUDGET | D85: 46266 | E85: R_DE_DE_A_ROAD | F85: DE | G85: DE_FC | H85: CARRIER_A | I85: ROAD | J85: 16000 | K85: 0.38 | L85: 0.97 | M85: 0.6 | N85: =J85*K85*L85*M85 -> 3538.56 | O85: 1.05 | P85: =N85*O85 -> 3715.488 | Q85: 0.78 | R85: =P85*Q85 -> 2898.0806 | S85: 0.05 | T85: =N85*S85 -> 176.928 | U85: 0.016 | V85: =P85*U85 -> 59.447808 | W85: EUR | X85: 2.2 | Y85: PERCENTAGE_OF_BASE_FREIGHT | Z85: 0.095 | AA85: 7.8 | AB85: 9 | AC85: =IF(W85="EUR",AA85,IF(W85="GBP",AB85,1)) -> 7.8 | AD85: =R85*X85 -> 6375.7774 | AE85: =IF(Y85="PERCENTAGE_OF_BASE_FREIGHT",AD85*Z85,IF(Y85="PER_CHARGEABLE_KG",R85*Z85,P85*Z85)) -> 605.69885 | AF85: =AD85*AC85 -> 49731.064 | AG85: =AE85*AC85 -> 4724.4511 | AH85: EUR | AI85: 1.18 | AJ85: =IF(AH85="EUR",AA85,IF(AH85="GBP",AB85,1)) -> 7.8 | AK85: =N85*AI85 -> 4175.5008 | AL85: =AK85*AJ85 -> 32568.906 | AM85: EUR | AN85: 0.42 | AO85: =IF(AM85="EUR",AA85,IF(AM85="GBP",AB85,1)) -> 7.8 | AP85: =P85*AN85 -> 1560.505 | AQ85: =AP85*AO85 -> 12171.939 | AR85: EUR | AS85: 3.2 | AT85: =IF(AR85="EUR",AA85,IF(AR85="GBP",AB85,1)) -> 7.8 | AU85: =T85*AS85 -> 566.1696 | AV85: =AU85*AT85 -> 4416.1229 | AW85: EUR | AX85: 2.3 | AY85: =IF(AW85="EUR",AA85,IF(AW85="GBP",AB85,1)) -> 7.8 | AZ85: =V85*AX85 -> 136.72996 | BA85: =AZ85*AY85 -> 1066.4937 | BB85: =AF85+AG85+AL85+AQ85+AV85+BA85 -> 104678.98 | BC85: 0.965 | BG85: UNVERIFIED_UNLIMITED_FOR_MVP
A86: BUDGET_2026_V1 | B86: BUDGET | D86: 46266 | E86: R_DE_DE_B_ROAD | F86: DE | G86: DE_FC | H86: CARRIER_B | I86: ROAD | J86: 16000 | K86: 0.38 | L86: 0.97 | M86: 0.4 | N86: =J86*K86*L86*M86 -> 2359.04 | O86: 1.05 | P86: =N86*O86 -> 2476.992 | Q86: 0.8 | R86: =P86*Q86 -> 1981.5936 | S86: 0.05 | T86: =N86*S86 -> 117.952 | U86: 0.013 | V86: =P86*U86 -> 32.200896 | W86: EUR | X86: 2.75 | Y86: PER_CHARGEABLE_KG | Z86: 0.21 | AA86: 7.8 | AB86: 9 | AC86: =IF(W86="EUR",AA86,IF(W86="GBP",AB86,1)) -> 7.8 | AD86: =R86*X86 -> 5449.3824 | AE86: =IF(Y86="PERCENTAGE_OF_BASE_FREIGHT",AD86*Z86,IF(Y86="PER_CHARGEABLE_KG",R86*Z86,P86*Z86)) -> 416.13466 | AF86: =AD86*AC86 -> 42505.183 | AG86: =AE86*AC86 -> 3245.8503 | AH86: EUR | AI86: 1.18 | AJ86: =IF(AH86="EUR",AA86,IF(AH86="GBP",AB86,1)) -> 7.8 | AK86: =N86*AI86 -> 2783.6672 | AL86: =AK86*AJ86 -> 21712.604 | AM86: EUR | AN86: 0.42 | AO86: =IF(AM86="EUR",AA86,IF(AM86="GBP",AB86,1)) -> 7.8 | AP86: =P86*AN86 -> 1040.3366 | AQ86: =AP86*AO86 -> 8114.6258 | AR86: EUR | AS86: 3.2 | AT86: =IF(AR86="EUR",AA86,IF(AR86="GBP",AB86,1)) -> 7.8 | AU86: =T86*AS86 -> 377.4464 | AV86: =AU86*AT86 -> 2944.0819 | AW86: EUR | AX86: 2.3 | AY86: =IF(AW86="EUR",AA86,IF(AW86="GBP",AB86,1)) -> 7.8 | AZ86: =V86*AX86 -> 74.062061 | BA86: =AZ86*AY86 -> 577.68407 | BB86: =AF86+AG86+AL86+AQ86+AV86+BA86 -> 79100.029 | BC86: 0.976 | BG86: UNVERIFIED_UNLIMITED_FOR_MVP
A87: BUDGET_2026_V1 | B87: BUDGET | D87: 46266 | E87: R_DE_FR_B_ROAD | F87: DE | G87: FR_FC | H87: CARRIER_B | I87: ROAD | J87: 16000 | K87: 0.38 | L87: 0.03 | M87: 1 | N87: =J87*K87*L87*M87 -> 182.4 | O87: 1.08 | P87: =N87*O87 -> 196.992 | Q87: 0.86 | R87: =P87*Q87 -> 169.41312 | S87: 0.05 | T87: =N87*S87 -> 9.12 | U87: 0.014 | V87: =P87*U87 -> 2.757888 | W87: EUR | X87: 3.3 | Y87: PER_CHARGEABLE_KG | Z87: 0.24 | AA87: 7.8 | AB87: 9 | AC87: =IF(W87="EUR",AA87,IF(W87="GBP",AB87,1)) -> 7.8 | AD87: =R87*X87 -> 559.0633 | AE87: =IF(Y87="PERCENTAGE_OF_BASE_FREIGHT",AD87*Z87,IF(Y87="PER_CHARGEABLE_KG",R87*Z87,P87*Z87)) -> 40.659149 | AF87: =AD87*AC87 -> 4360.6937 | AG87: =AE87*AC87 -> 317.14136 | AH87: EUR | AI87: 1.05 | AJ87: =IF(AH87="EUR",AA87,IF(AH87="GBP",AB87,1)) -> 7.8 | AK87: =N87*AI87 -> 191.52 | AL87: =AK87*AJ87 -> 1493.856 | AM87: EUR | AN87: 0.38 | AO87: =IF(AM87="EUR",AA87,IF(AM87="GBP",AB87,1)) -> 7.8 | AP87: =P87*AN87 -> 74.85696 | AQ87: =AP87*AO87 -> 583.88429 | AR87: EUR | AS87: 3.8 | AT87: =IF(AR87="EUR",AA87,IF(AR87="GBP",AB87,1)) -> 7.8 | AU87: =T87*AS87 -> 34.656 | AV87: =AU87*AT87 -> 270.3168 | AW87: EUR | AX87: 2.3 | AY87: =IF(AW87="EUR",AA87,IF(AW87="GBP",AB87,1)) -> 7.8 | AZ87: =V87*AX87 -> 6.3431424 | BA87: =AZ87*AY87 -> 49.476511 | BB87: =AF87+AG87+AL87+AQ87+AV87+BA87 -> 7075.3687 | BC87: 0.968 | BG87: UNVERIFIED_UNLIMITED_FOR_MVP
A88: BUDGET_2026_V1 | B88: BUDGET | D88: 46266 | E88: R_FR_FR_A_ROAD | F88: FR | G88: FR_FC | H88: CARRIER_A | I88: ROAD | J88: 16000 | K88: 0.31 | L88: 1 | M88: 0.35 | N88: =J88*K88*L88*M88 -> 1736 | O88: 1.06 | P88: =N88*O88 -> 1840.16 | Q88: 0.76 | R88: =P88*Q88 -> 1398.5216 | S88: 0.06 | T88: =N88*S88 -> 104.16 | U88: 0.017 | V88: =P88*U88 -> 31.28272 | W88: EUR | X88: 2.1 | Y88: PERCENTAGE_OF_BASE_FREIGHT | Z88: 0.09 | AA88: 7.8 | AB88: 9 | AC88: =IF(W88="EUR",AA88,IF(W88="GBP",AB88,1)) -> 7.8 | AD88: =R88*X88 -> 2936.8954 | AE88: =IF(Y88="PERCENTAGE_OF_BASE_FREIGHT",AD88*Z88,IF(Y88="PER_CHARGEABLE_KG",R88*Z88,P88*Z88)) -> 264.32058 | AF88: =AD88*AC88 -> 22907.784 | AG88: =AE88*AC88 -> 2061.7005 | AH88: EUR | AI88: 1.05 | AJ88: =IF(AH88="EUR",AA88,IF(AH88="GBP",AB88,1)) -> 7.8 | AK88: =N88*AI88 -> 1822.8 | AL88: =AK88*AJ88 -> 14217.84 | AM88: EUR | AN88: 0.38 | AO88: =IF(AM88="EUR",AA88,IF(AM88="GBP",AB88,1)) -> 7.8 | AP88: =P88*AN88 -> 699.2608 | AQ88: =AP88*AO88 -> 5454.2342 | AR88: EUR | AS88: 3 | AT88: =IF(AR88="EUR",AA88,IF(AR88="GBP",AB88,1)) -> 7.8 | AU88: =T88*AS88 -> 312.48 | AV88: =AU88*AT88 -> 2437.344 | AW88: EUR | AX88: 2.3 | AY88: =IF(AW88="EUR",AA88,IF(AW88="GBP",AB88,1)) -> 7.8 | AZ88: =V88*AX88 -> 71.950256 | BA88: =AZ88*AY88 -> 561.212 | BB88: =AF88+AG88+AL88+AQ88+AV88+BA88 -> 47640.115 | BC88: 0.961 | BG88: UNVERIFIED_UNLIMITED_FOR_MVP
A89: BUDGET_2026_V1 | B89: BUDGET | D89: 46266 | E89: R_FR_FR_B_ROAD | F89: FR | G89: FR_FC | H89: CARRIER_B | I89: ROAD | J89: 16000 | K89: 0.31 | L89: 1 | M89: 0.65 | N89: =J89*K89*L89*M89 -> 3224 | O89: 1.06 | P89: =N89*O89 -> 3417.44 | Q89: 0.79 | R89: =P89*Q89 -> 2699.7776 | S89: 0.06 | T89: =N89*S89 -> 193.44 | U89: 0.014 | V89: =P89*U89 -> 47.84416 | W89: EUR | X89: 2.6 | Y89: PER_CHARGEABLE_KG | Z89: 0.2 | AA89: 7.8 | AB89: 9 | AC89: =IF(W89="EUR",AA89,IF(W89="GBP",AB89,1)) -> 7.8 | AD89: =R89*X89 -> 7019.4218 | AE89: =IF(Y89="PERCENTAGE_OF_BASE_FREIGHT",AD89*Z89,IF(Y89="PER_CHARGEABLE_KG",R89*Z89,P89*Z89)) -> 539.95552 | AF89: =AD89*AC89 -> 54751.49 | AG89: =AE89*AC89 -> 4211.6531 | AH89: EUR | AI89: 1.05 | AJ89: =IF(AH89="EUR",AA89,IF(AH89="GBP",AB89,1)) -> 7.8 | AK89: =N89*AI89 -> 3385.2 | AL89: =AK89*AJ89 -> 26404.56 | AM89: EUR | AN89: 0.38 | AO89: =IF(AM89="EUR",AA89,IF(AM89="GBP",AB89,1)) -> 7.8 | AP89: =P89*AN89 -> 1298.6272 | AQ89: =AP89*AO89 -> 10129.292 | AR89: EUR | AS89: 3 | AT89: =IF(AR89="EUR",AA89,IF(AR89="GBP",AB89,1)) -> 7.8 | AU89: =T89*AS89 -> 580.32 | AV89: =AU89*AT89 -> 4526.496 | AW89: EUR | AX89: 2.3 | AY89: =IF(AW89="EUR",AA89,IF(AW89="GBP",AB89,1)) -> 7.8 | AZ89: =V89*AX89 -> 110.04157 | BA89: =AZ89*AY89 -> 858.32423 | BB89: =AF89+AG89+AL89+AQ89+AV89+BA89 -> 100881.82 | BC89: 0.973 | BG89: UNVERIFIED_UNLIMITED_FOR_MVP
A90: BUDGET_2026_V1 | B90: BUDGET | D90: 46266 | E90: R_GB_DE_A_ROAD | F90: GB | G90: DE_FC | H90: CARRIER_A | I90: ROAD | J90: 16000 | K90: 0.31 | L90: 0.96 | M90: 0.65 | N90: =J90*K90*L90*M90 -> 3095.04 | O90: 1.12 | P90: =N90*O90 -> 3466.4448 | Q90: 1.02 | R90: =P90*Q90 -> 3535.7737 | S90: 0.08 | T90: =N90*S90 -> 247.6032 | U90: 0.022 | V90: =P90*U90 -> 76.261786 | W90: GBP | X90: 4 | Y90: PERCENTAGE_OF_BASE_FREIGHT | Z90: 0.1 | AA90: 7.8 | AB90: 9 | AC90: =IF(W90="EUR",AA90,IF(W90="GBP",AB90,1)) -> 9 | AD90: =R90*X90 -> 14143.095 | AE90: =IF(Y90="PERCENTAGE_OF_BASE_FREIGHT",AD90*Z90,IF(Y90="PER_CHARGEABLE_KG",R90*Z90,P90*Z90)) -> 1414.3095 | AF90: =AD90*AC90 -> 127287.85 | AG90: =AE90*AC90 -> 12728.785 | AH90: EUR | AI90: 1.18 | AJ90: =IF(AH90="EUR",AA90,IF(AH90="GBP",AB90,1)) -> 7.8 | AK90: =N90*AI90 -> 3652.1472 | AL90: =AK90*AJ90 -> 28486.748 | AM90: EUR | AN90: 0.42 | AO90: =IF(AM90="EUR",AA90,IF(AM90="GBP",AB90,1)) -> 7.8 | AP90: =P90*AN90 -> 1455.9068 | AQ90: =AP90*AO90 -> 11356.073 | AR90: GBP | AS90: 4.8 | AT90: =IF(AR90="EUR",AA90,IF(AR90="GBP",AB90,1)) -> 9 | AU90: =T90*AS90 -> 1188.4954 | AV90: =AU90*AT90 -> 10696.458 | AW90: GBP | AX90: 2.3 | AY90: =IF(AW90="EUR",AA90,IF(AW90="GBP",AB90,1)) -> 9 | AZ90: =V90*AX90 -> 175.40211 | BA90: =AZ90*AY90 -> 1578.619 | BB90: =AF90+AG90+AL90+AQ90+AV90+BA90 -> 192134.54 | BC90: 0.93 | BG90: UNVERIFIED_UNLIMITED_FOR_MVP
A91: BUDGET_2026_V1 | B91: BUDGET | D91: 46266 | E91: R_GB_DE_B_ROAD | F91: GB | G91: DE_FC | H91: CARRIER_B | I91: ROAD | J91: 16000 | K91: 0.31 | L91: 0.96 | M91: 0.25 | N91: =J91*K91*L91*M91 -> 1190.4 | O91: 1.12 | P91: =N91*O91 -> 1333.248 | Q91: 1 | R91: =P91*Q91 -> 1333.248 | S91: 0.08 | T91: =N91*S91 -> 95.232 | U91: 0.017 | V91: =P91*U91 -> 22.665216 | W91: GBP | X91: 4.7 | Y91: PER_CHARGEABLE_KG | Z91: 0.33 | AA91: 7.8 | AB91: 9 | AC91: =IF(W91="EUR",AA91,IF(W91="GBP",AB91,1)) -> 9 | AD91: =R91*X91 -> 6266.2656 | AE91: =IF(Y91="PERCENTAGE_OF_BASE_FREIGHT",AD91*Z91,IF(Y91="PER_CHARGEABLE_KG",R91*Z91,P91*Z91)) -> 439.97184 | AF91: =AD91*AC91 -> 56396.39 | AG91: =AE91*AC91 -> 3959.7466 | AH91: EUR | AI91: 1.18 | AJ91: =IF(AH91="EUR",AA91,IF(AH91="GBP",AB91,1)) -> 7.8 | AK91: =N91*AI91 -> 1404.672 | AL91: =AK91*AJ91 -> 10956.442 | AM91: EUR | AN91: 0.42 | AO91: =IF(AM91="EUR",AA91,IF(AM91="GBP",AB91,1)) -> 7.8 | AP91: =P91*AN91 -> 559.96416 | AQ91: =AP91*AO91 -> 4367.7204 | AR91: GBP | AS91: 4.8 | AT91: =IF(AR91="EUR",AA91,IF(AR91="GBP",AB91,1)) -> 9 | AU91: =T91*AS91 -> 457.1136 | AV91: =AU91*AT91 -> 4114.0224 | AW91: GBP | AX91: 2.3 | AY91: =IF(AW91="EUR",AA91,IF(AW91="GBP",AB91,1)) -> 9 | AZ91: =V91*AX91 -> 52.129997 | BA91: =AZ91*AY91 -> 469.16997 | BB91: =AF91+AG91+AL91+AQ91+AV91+BA91 -> 80263.491 | BC91: 0.95 | BG91: UNVERIFIED_UNLIMITED_FOR_MVP
A92: BUDGET_2026_V1 | B92: BUDGET | D92: 46266 | E92: R_GB_DE_B_AIR | F92: GB | G92: DE_FC | H92: CARRIER_B | I92: AIR | J92: 16000 | K92: 0.31 | L92: 0.96 | M92: 0.07 | N92: =J92*K92*L92*M92 -> 333.312 | O92: 1.12 | P92: =N92*O92 -> 373.30944 | Q92: 0.94 | R92: =P92*Q92 -> 350.91087 | S92: 0.08 | T92: =N92*S92 -> 26.66496 | U92: 0.013 | V92: =P92*U92 -> 4.8530227 | W92: GBP | X92: 6.2 | Y92: PERCENTAGE_OF_BASE_FREIGHT | Z92: 0.115 | AA92: 7.8 | AB92: 9 | AC92: =IF(W92="EUR",AA92,IF(W92="GBP",AB92,1)) -> 9 | AD92: =R92*X92 -> 2175.6474 | AE92: =IF(Y92="PERCENTAGE_OF_BASE_FREIGHT",AD92*Z92,IF(Y92="PER_CHARGEABLE_KG",R92*Z92,P92*Z92)) -> 250.19945 | AF92: =AD92*AC92 -> 19580.827 | AG92: =AE92*AC92 -> 2251.7951 | AH92: EUR | AI92: 1.18 | AJ92: =IF(AH92="EUR",AA92,IF(AH92="GBP",AB92,1)) -> 7.8 | AK92: =N92*AI92 -> 393.30816 | AL92: =AK92*AJ92 -> 3067.8036 | AM92: EUR | AN92: 0.42 | AO92: =IF(AM92="EUR",AA92,IF(AM92="GBP",AB92,1)) -> 7.8 | AP92: =P92*AN92 -> 156.78996 | AQ92: =AP92*AO92 -> 1222.9617 | AR92: GBP | AS92: 4.8 | AT92: =IF(AR92="EUR",AA92,IF(AR92="GBP",AB92,1)) -> 9 | AU92: =T92*AS92 -> 127.99181 | AV92: =AU92*AT92 -> 1151.9263 | AW92: GBP | AX92: 2.8 | AY92: =IF(AW92="EUR",AA92,IF(AW92="GBP",AB92,1)) -> 9 | AZ92: =V92*AX92 -> 13.588464 | BA92: =AZ92*AY92 -> 122.29617 | BB92: =AF92+AG92+AL92+AQ92+AV92+BA92 -> 27397.61 | BC92: 0.974 | BG92: UNVERIFIED_UNLIMITED_FOR_MVP
A93: BUDGET_2026_V1 | B93: BUDGET | D93: 46266 | E93: R_GB_DE_C_AIR | F93: GB | G93: DE_FC | H93: CARRIER_C | I93: AIR | J93: 16000 | K93: 0.31 | L93: 0.96 | M93: 0.03 | N93: =J93*K93*L93*M93 -> 142.848 | O93: 1.12 | P93: =N93*O93 -> 159.98976 | Q93: 0.92 | R93: =P93*Q93 -> 147.19058 | S93: 0.08 | T93: =N93*S93 -> 11.42784 | U93: 0.009 | V93: =P93*U93 -> 1.4399078 | W93: GBP | X93: 7.5 | Y93: PER_CHARGEABLE_KG | Z93: 0.58 | AA93: 7.8 | AB93: 9 | AC93: =IF(W93="EUR",AA93,IF(W93="GBP",AB93,1)) -> 9 | AD93: =R93*X93 -> 1103.9293 | AE93: =IF(Y93="PERCENTAGE_OF_BASE_FREIGHT",AD93*Z93,IF(Y93="PER_CHARGEABLE_KG",R93*Z93,P93*Z93)) -> 85.370536 | AF93: =AD93*AC93 -> 9935.3641 | AG93: =AE93*AC93 -> 768.33482 | AH93: EUR | AI93: 1.18 | AJ93: =IF(AH93="EUR",AA93,IF(AH93="GBP",AB93,1)) -> 7.8 | AK93: =N93*AI93 -> 168.56064 | AL93: =AK93*AJ93 -> 1314.773 | AM93: EUR | AN93: 0.42 | AO93: =IF(AM93="EUR",AA93,IF(AM93="GBP",AB93,1)) -> 7.8 | AP93: =P93*AN93 -> 67.195699 | AQ93: =AP93*AO93 -> 524.12645 | AR93: GBP | AS93: 4.8 | AT93: =IF(AR93="EUR",AA93,IF(AR93="GBP",AB93,1)) -> 9 | AU93: =T93*AS93 -> 54.853632 | AV93: =AU93*AT93 -> 493.68269 | AW93: GBP | AX93: 3.6 | AY93: =IF(AW93="EUR",AA93,IF(AW93="GBP",AB93,1)) -> 9 | AZ93: =V93*AX93 -> 5.1836682 | BA93: =AZ93*AY93 -> 46.653014 | BB93: =AF93+AG93+AL93+AQ93+AV93+BA93 -> 13082.934 | BC93: 0.988 | BG93: UNVERIFIED_UNLIMITED_FOR_MVP
A94: BUDGET_2026_V1 | B94: BUDGET | D94: 46266 | E94: R_GB_FR_B_AIR | F94: GB | G94: FR_FC | H94: CARRIER_B | I94: AIR | J94: 16000 | K94: 0.31 | L94: 0.04 | M94: 1 | N94: =J94*K94*L94*M94 -> 198.4 | O94: 1.15 | P94: =N94*O94 -> 228.16 | Q94: 0.9 | R94: =P94*Q94 -> 205.344 | S94: 0.08 | T94: =N94*S94 -> 15.872 | U94: 0.012 | V94: =P94*U94 -> 2.73792 | W94: EUR | X94: 6.7 | Y94: PERCENTAGE_OF_BASE_FREIGHT | Z94: 0.105 | AA94: 7.8 | AB94: 9 | AC94: =IF(W94="EUR",AA94,IF(W94="GBP",AB94,1)) -> 7.8 | AD94: =R94*X94 -> 1375.8048 | AE94: =IF(Y94="PERCENTAGE_OF_BASE_FREIGHT",AD94*Z94,IF(Y94="PER_CHARGEABLE_KG",R94*Z94,P94*Z94)) -> 144.4595 | AF94: =AD94*AC94 -> 10731.277 | AG94: =AE94*AC94 -> 1126.7841 | AH94: EUR | AI94: 1.05 | AJ94: =IF(AH94="EUR",AA94,IF(AH94="GBP",AB94,1)) -> 7.8 | AK94: =N94*AI94 -> 208.32 | AL94: =AK94*AJ94 -> 1624.896 | AM94: EUR | AN94: 0.38 | AO94: =IF(AM94="EUR",AA94,IF(AM94="GBP",AB94,1)) -> 7.8 | AP94: =P94*AN94 -> 86.7008 | AQ94: =AP94*AO94 -> 676.26624 | AR94: EUR | AS94: 5.2 | AT94: =IF(AR94="EUR",AA94,IF(AR94="GBP",AB94,1)) -> 7.8 | AU94: =T94*AS94 -> 82.5344 | AV94: =AU94*AT94 -> 643.76832 | AW94: EUR | AX94: 2.8 | AY94: =IF(AW94="EUR",AA94,IF(AW94="GBP",AB94,1)) -> 7.8 | AZ94: =V94*AX94 -> 7.666176 | BA94: =AZ94*AY94 -> 59.796173 | BB94: =AF94+AG94+AL94+AQ94+AV94+BA94 -> 14862.788 | BC94: 0.971 | BG94: UNVERIFIED_UNLIMITED_FOR_MVP
A95: BUDGET_2026_V1 | B95: BUDGET | D95: 46296 | E95: R_DE_DE_A_ROAD | F95: DE | G95: DE_FC | H95: CARRIER_A | I95: ROAD | J95: 18000 | K95: 0.36 | L95: 0.97 | M95: 0.6 | N95: =J95*K95*L95*M95 -> 3771.36 | O95: 1.05 | P95: =N95*O95 -> 3959.928 | Q95: 0.7878 | R95: =P95*Q95 -> 3119.6313 | S95: 0.05 | T95: =N95*S95 -> 188.568 | U95: 0.016 | V95: =P95*U95 -> 63.358848 | W95: EUR | X95: 2.2 | Y95: PERCENTAGE_OF_BASE_FREIGHT | Z95: 0.095 | AA95: 7.8 | AB95: 9 | AC95: =IF(W95="EUR",AA95,IF(W95="GBP",AB95,1)) -> 7.8 | AD95: =R95*X95 -> 6863.1888 | AE95: =IF(Y95="PERCENTAGE_OF_BASE_FREIGHT",AD95*Z95,IF(Y95="PER_CHARGEABLE_KG",R95*Z95,P95*Z95)) -> 652.00294 | AF95: =AD95*AC95 -> 53532.873 | AG95: =AE95*AC95 -> 5085.6229 | AH95: EUR | AI95: 1.18 | AJ95: =IF(AH95="EUR",AA95,IF(AH95="GBP",AB95,1)) -> 7.8 | AK95: =N95*AI95 -> 4450.2048 | AL95: =AK95*AJ95 -> 34711.597 | AM95: EUR | AN95: 0.42 | AO95: =IF(AM95="EUR",AA95,IF(AM95="GBP",AB95,1)) -> 7.8 | AP95: =P95*AN95 -> 1663.1698 | AQ95: =AP95*AO95 -> 12972.724 | AR95: EUR | AS95: 3.2 | AT95: =IF(AR95="EUR",AA95,IF(AR95="GBP",AB95,1)) -> 7.8 | AU95: =T95*AS95 -> 603.4176 | AV95: =AU95*AT95 -> 4706.6573 | AW95: EUR | AX95: 2.3 | AY95: =IF(AW95="EUR",AA95,IF(AW95="GBP",AB95,1)) -> 7.8 | AZ95: =V95*AX95 -> 145.72535 | BA95: =AZ95*AY95 -> 1136.6577 | BB95: =AF95+AG95+AL95+AQ95+AV95+BA95 -> 112146.13 | BC95: 0.965 | BG95: UNVERIFIED_UNLIMITED_FOR_MVP
A96: BUDGET_2026_V1 | B96: BUDGET | D96: 46296 | E96: R_DE_DE_B_ROAD | F96: DE | G96: DE_FC | H96: CARRIER_B | I96: ROAD | J96: 18000 | K96: 0.36 | L96: 0.97 | M96: 0.4 | N96: =J96*K96*L96*M96 -> 2514.24 | O96: 1.05 | P96: =N96*O96 -> 2639.952 | Q96: 0.808 | R96: =P96*Q96 -> 2133.0812 | S96: 0.05 | T96: =N96*S96 -> 125.712 | U96: 0.013 | V96: =P96*U96 -> 34.319376 | W96: EUR | X96: 2.75 | Y96: PER_CHARGEABLE_KG | Z96: 0.21 | AA96: 7.8 | AB96: 9 | AC96: =IF(W96="EUR",AA96,IF(W96="GBP",AB96,1)) -> 7.8 | AD96: =R96*X96 -> 5865.9733 | AE96: =IF(Y96="PERCENTAGE_OF_BASE_FREIGHT",AD96*Z96,IF(Y96="PER_CHARGEABLE_KG",R96*Z96,P96*Z96)) -> 447.94706 | AF96: =AD96*AC96 -> 45754.592 | AG96: =AE96*AC96 -> 3493.987 | AH96: EUR | AI96: 1.18 | AJ96: =IF(AH96="EUR",AA96,IF(AH96="GBP",AB96,1)) -> 7.8 | AK96: =N96*AI96 -> 2966.8032 | AL96: =AK96*AJ96 -> 23141.065 | AM96: EUR | AN96: 0.42 | AO96: =IF(AM96="EUR",AA96,IF(AM96="GBP",AB96,1)) -> 7.8 | AP96: =P96*AN96 -> 1108.7798 | AQ96: =AP96*AO96 -> 8648.4828 | AR96: EUR | AS96: 3.2 | AT96: =IF(AR96="EUR",AA96,IF(AR96="GBP",AB96,1)) -> 7.8 | AU96: =T96*AS96 -> 402.2784 | AV96: =AU96*AT96 -> 3137.7715 | AW96: EUR | AX96: 2.3 | AY96: =IF(AW96="EUR",AA96,IF(AW96="GBP",AB96,1)) -> 7.8 | AZ96: =V96*AX96 -> 78.934565 | BA96: =AZ96*AY96 -> 615.68961 | BB96: =AF96+AG96+AL96+AQ96+AV96+BA96 -> 84791.588 | BC96: 0.976 | BG96: UNVERIFIED_UNLIMITED_FOR_MVP
... A194: ACTUAL_2026_08_CLOSE_V1 | B194: ACTUAL | D194: 46204 | E194: R_GB_FR_B_AIR | F194: GB | G194: FR_FC | H194: CARRIER_B | I194: AIR | J194: 18000 | K194: 0.33 | L194: 0.04 | M194: 1 | N194: =J194*K194*L194*M194 -> 237.6 | O194: 1.1569 | P194: =N194*O194 -> 274.87944 | Q194: 0.9045 | R194: =P194*Q194 -> 248.62845 | S194: 0.08 | T194: =N194*S194 -> 19.008 | U194: 0.01224 | V194: =P194*U194 -> 3.3645243 | W194: EUR | X194: 6.7938 | Y194: PERCENTAGE_OF_BASE_FREIGHT | Z194: 0.10647 | AA194: 7.91 | AB194: 9.18 | AC194: =IF(W194="EUR",AA194,IF(W194="GBP",AB194,1)) -> 7.91 | AD194: =R194*X194 -> 1689.132 | AE194: =IF(Y194="PERCENTAGE_OF_BASE_FREIGHT",AD194*Z194,IF(Y194="PER_CHARGEABLE_KG",R194*Z194,P194*Z194)) -> 179.84188 | AF194: =AD194*AC194 -> 13361.034 | AG194: =AE194*AC194 -> 1422.5493 | AH194: EUR | AI194: 1.0647 | AJ194: =IF(AH194="EUR",AA194,IF(AH194="GBP",AB194,1)) -> 7.91 | AK194: =N194*AI194 -> 252.97272 | AL194: =AK194*AJ194 -> 2001.0142 | AM194: EUR | AN194: 0.38532 | AO194: =IF(AM194="EUR",AA194,IF(AM194="GBP",AB194,1)) -> 7.91 | AP194: =P194*AN194 -> 105.91655 | AQ194: =AP194*AO194 -> 837.79988 | AR194: EUR | AS194: 5.2728 | AT194: =IF(AR194="EUR",AA194,IF(AR194="GBP",AB194,1)) -> 7.91 | AU194: =T194*AS194 -> 100.22538 | AV194: =AU194*AT194 -> 792.78277 | AW194: EUR | AX194: 2.8392 | AY194: =IF(AW194="EUR",AA194,IF(AW194="GBP",AB194,1)) -> 7.91 | AZ194: =V194*AX194 -> 9.5525575 | BA194: =AZ194*AY194 -> 75.56073 | BB194: =AF194+AG194+AL194+AQ194+AV194+BA194 -> 18490.741 | BC194: 0.968 | BG194: UNVERIFIED_UNLIMITED_FOR_MVP
A195: ACTUAL_2026_08_CLOSE_V1 | B195: ACTUAL | D195: 46235 | E195: R_DE_DE_A_ROAD | F195: DE | G195: DE_FC | H195: CARRIER_A | I195: ROAD | J195: 20300 | K195: 0.31 | L195: 0.97 | M195: 0.6 | N195: =J195*K195*L195*M195 -> 3662.526 | O195: 1.05 | P195: =N195*O195 -> 3845.6523 | Q195: 0.78 | R195: =P195*Q195 -> 2999.6088 | S195: 0.05 | T195: =N195*S195 -> 183.1263 | U195: 0.016 | V195: =P195*U195 -> 61.530437 | W195: EUR | X195: 2.2352 | Y195: PERCENTAGE_OF_BASE_FREIGHT | Z195: 0.09652 | AA195: 7.95 | AB195: 9.22 | AC195: =IF(W195="EUR",AA195,IF(W195="GBP",AB195,1)) -> 7.95 | AD195: =R195*X195 -> 6704.7256 | AE195: =IF(Y195="PERCENTAGE_OF_BASE_FREIGHT",AD195*Z195,IF(Y195="PER_CHARGEABLE_KG",R195*Z195,P195*Z195)) -> 647.14011 | AF195: =AD195*AC195 -> 53302.568 | AG195: =AE195*AC195 -> 5144.7639 | AH195: EUR | AI195: 1.3884759 | AJ195: =IF(AH195="EUR",AA195,IF(AH195="GBP",AB195,1)) -> 7.95 | AK195: =N195*AI195 -> 5085.3292 | AL195: =AK195*AJ195 -> 40428.367 | AM195: EUR | AN195: 0.42672 | AO195: =IF(AM195="EUR",AA195,IF(AM195="GBP",AB195,1)) -> 7.95 | AP195: =P195*AN195 -> 1641.0167 | AQ195: =AP195*AO195 -> 13046.083 | AR195: EUR | AS195: 3.2512 | AT195: =IF(AR195="EUR",AA195,IF(AR195="GBP",AB195,1)) -> 7.95 | AU195: =T195*AS195 -> 595.38023 | AV195: =AU195*AT195 -> 4733.2728 | AW195: EUR | AX195: 2.3368 | AY195: =IF(AW195="EUR",AA195,IF(AW195="GBP",AB195,1)) -> 7.95 | AZ195: =V195*AX195 -> 143.78432 | BA195: =AZ195*AY195 -> 1143.0854 | BB195: =AF195+AG195+AL195+AQ195+AV195+BA195 -> 117798.14 | BC195: 0.962 | BD195: UK promotion | BE195: 为维持促销期间履约时效，提高德国仓至英国的空运和 Carrier C 份额 | BG195: UNVERIFIED_UNLIMITED_FOR_MVP
...

Sheet Cost_Facts
A1: 履约变动成本事实
A2: 每条成本事实与 Model_Calc 的线路公式列直接勾稽；Actual 权威金额差异必须为零。
A4: Version | B4: Type | C4: Scenario | D4: Month | E4: Route | F4: Destination | G4: FC | H4: Carrier | I4: Mode | J4: Cost Component | K4: Currency | L4: Original Amount | M4: FX | N4: High Precision CNY (text) | O4: Report CNY | P4: Authority CNY | Q4: Authority Delta | R4: Posting Basis | S4: Model Recalc CNY | T4: Recalc Delta
A5: BUDGET_2026_V1 | B5: BUDGET | D5: 46023 | E5: R_DE_DE_A_ROAD | F5: DE | G5: DE_FC | H5: CARRIER_A | I5: ROAD | J5: BASE_FREIGHT | K5: EUR | L5: 6166.0479 | M5: 7.8 | N5: 48095.17352640000000 | O5: 48095.173 | R5: INVOICE_OR_PLAN | S5: =Model_Calc!AF5 -> 48095.174 | T5: =ROUND(S5-O5,4) -> 0
A6: BUDGET_2026_V1 | B6: BUDGET | D6: 46023 | E6: R_DE_DE_A_ROAD | F6: DE | G6: DE_FC | H6: CARRIER_A | I6: ROAD | J6: FUEL_SURCHARGE | K6: EUR | L6: 585.77455 | M6: 7.8 | N6: 4569.04148500800000000 | O6: 4569.0415 | R6: INVOICE_OR_PLAN | S6: =Model_Calc!AG5 -> 4569.0415 | T6: =ROUND(S6-O6,4) -> 0
